Workbook
Name List_Experiment_ID: 'Master_Experiments'!$A$2:INDEX('Master_Experiments'!$A:$A,MATCH("zzz",'Master_Experiments'!$A:$A))
Name List_Search_Space_ID: 'Search_Spaces'!$A$3:INDEX('Search_Spaces'!$A:$A,MATCH("zzz",'Search_Spaces'!$A:$A))
Name List_Study_ID: 'Study_Design'!$A$3:INDEX('Study_Design'!$A:$A,MATCH("zzz",'Study_Design'!$A:$A))
Name List_Data_Slice_ID: 'Data_Selection_Design'!$A$2:INDEX('Data_Selection_Design'!$A:$A,MATCH("zzz",'Data_Selection_Design'!$A:$A))
Name List_Grouping_Strategy_ID: 'Grouping_Strategy_Map'!$A$2:INDEX('Grouping_Strategy_Map'!$A:$A,MATCH("zzz",'Grouping_Strategy_Map'!$A:$A))
Name List_Category: 'Dictionary_Validation'!$A$3:$A$9
Name List_Evidential_Role: 'Dictionary_Validation'!$B$3:$B$7
Name List_Stage: 'Dictionary_Validation'!$C$3:$C$9
Name List_Priority: 'Dictionary_Validation'!$D$3:$D$6
Name List_Status: 'Dictionary_Validation'!$E$3:$E$8
Name List_Reporting_Destination: 'Dictionary_Validation'!$F$3:$F$7
Name List_Reviewed: 'Dictionary_Validation'!$G$3:$G$4
Name List_Used_in_Thesis: 'Dictionary_Validation'!$H$3:$H$4
Name List_Freeze_Status: 'Dictionary_Validation'!$I$3:$I$4
Name List_Run_Type: 'Dictionary_Validation'!$J$3:$J$7
Name List_Affects_Frozen_Pipeline: 'Dictionary_Validation'!$K$3:$K$4
Name List_Eligible_for_Method_Decision: 'Dictionary_Validation'!$L$3:$L$4
Name List_Claim_Type: 'Dictionary_Validation'!$M$3:$M$6
Name List_Evidence_Status: 'Dictionary_Validation'!$N$3:$N$5
Name List_Writing_Location: 'Dictionary_Validation'!$O$3:$O$6
Name List_Human_Verification_Status: 'Dictionary_Validation'!$P$3:$P$5
Name List_Ethics_Status: 'Dictionary_Validation'!$Q$3:$Q$5
Name List_Ethics_Topic: 'Dictionary_Validation'!$R$3:$R$8
Name List_Required_for_Main_Claim: 'Dictionary_Validation'!$S$3:$S$4
Name List_Ready_for_Chapter_4: 'Dictionary_Validation'!$T$3:$T$4
Name List_YesNo: 'Dictionary_Validation'!$U$3:$U$4
Name List_Subject_Scope: 'Dictionary_Validation'!$V$3:$V$5
Name List_Session_Scope: 'Dictionary_Validation'!$W$3:$W$7
Name List_Task_Scope: 'Dictionary_Validation'!$X$3:$X$7
Name List_Modality_Scope: 'Dictionary_Validation'!$Y$3:$Y$6
Name List_Class_Balance_Policy: 'Dictionary_Validation'!$Z$3:$Z$6
Name List_Split_Family: 'Dictionary_Validation'!$AA$3:$AA$7
Name List_Imbalance_Status: 'Dictionary_Validation'!$AB$3:$AB$6
Name List_Leakage_Check_Status: 'Dictionary_Validation'!$AC$3:$AC$6
Name List_Thesis_Use_Tag: 'Dictionary_Validation'!$AD$3:$AD$7
Name List_Use_Case: 'Dictionary_Validation'!$AE$3:$AE$9
Name List_Group_Unit: 'Dictionary_Validation'!$AF$3:$AF$9
Name List_Grouping_Level: 'Dictionary_Validation'!$AG$3:$AG$9
Name List_Transfer_Direction: 'Dictionary_Validation'!$AH$3:$AH$7
Name List_Leakage_Risk_Level: 'Dictionary_Validation'!$AI$3:$AI$6
Name List_Target_Type: 'Dictionary_Validation'!$AJ$3:$AJ$6
Name List_Execution_Section: 'Dictionary_Validation'!$AK$3:$AK$9
Name List_Reuse_Policy: 'Dictionary_Validation'!$AL$3:$AL$5
Name List_Search_Optimization_Mode: 'Dictionary_Validation'!$AM$3:$AM$4
Name List_Search_Parameter_Scope: 'Dictionary_Validation'!$AN$3:$AN$5
Name List_Study_Type: 'Dictionary_Validation'!$AO$3:$AO$6
Name List_Study_Intent: 'Dictionary_Validation'!$AP$3:$AP$4
Name List_Factor_Type: 'Dictionary_Validation'!$AQ$3:$AQ$6
Name List_Replication_Mode: 'Dictionary_Validation'!$AR$3:$AR$5
Name List_Replication_Strategy: 'Dictionary_Validation'!$AS$3:$AS$6
Name List_Blocking_Strategy: 'Dictionary_Validation'!$AT$3:$AT$7
Name List_Randomization_Strategy: 'Dictionary_Validation'!$AU$3:$AU$7
Name List_Random_Seed_Policy: 'Dictionary_Validation'!$AV$3:$AV$5
Name List_Block_Type: 'Dictionary_Validation'!$AW$3:$AW$7
Name List_Design_Cell_Status: 'Dictionary_Validation'!$AX$3:$AX$7
Name List_Aggregation_Level: 'Dictionary_Validation'!$AY$3:$AY$7
Name List_Uncertainty_Method: 'Dictionary_Validation'!$AZ$3:$AZ$7
Name List_Multiplicity_Handling: 'Dictionary_Validation'!$BA$3:$BA$8
Name List_Interaction_Reporting_Policy: 'Dictionary_Validation'!$BB$3:$BB$6

Sheet README
A1: Thesis Experiment Program Workbook (v2)
A3: Purpose | B3: Scientific control system for thesis experiment governance: pre-interpretation design, lock tracking, leakage-aware execution traceability, and chapter-ready evidence mapping.
A6: Governance layers | B6: Experiment governance documents what each experiment is allowed to conclude. Data-slice governance documents what subset policy and grouping strategy were used in each run and what claims they can support.
A9: Evidence tiers | B9: Primary confirmatory; Primary-supporting robustness; Secondary decision-support; Exploratory extension. Each tier has explicit interpretation boundaries.
A12: Stage system | B12: Stage 1 Target lock -> Stage 2 Split lock -> Stage 3 Model lock -> Stage 4 Feature/preprocessing lock -> Stage 5 Confirmatory analysis -> Stage 6 Robustness analysis -> Stage 7 Exploratory extension.
A15: Freeze policy | B15: Confirmatory eligibility requires D01-D07 locked in Decision_Log. Chapter 4 readiness additionally requires required confirmatory/supporting items completed and marked Ready_for_Chapter_4=YES.
A18: Data_Selection_Design | B18: Defines allowed data slices (subject/session/task/modality/target scope, inclusion/exclusion, class-balance policy, leakage risk, and thesis-use boundary).
A21: Grouping_Strategy_Map | B21: Defines split family, train/test grouping units, leakage safeguards, and interpretation boundaries for each grouping strategy identifier.
A24: Data_Profile | B24: Structured worksheet for manual or imported descriptive counts by subject/session/task/modality/target/class and by Data_Slice_ID, with formula-based sparsity/imbalance flags.
A27: Claim boundaries | B27: Within-person held-out-session claims and cross-person transfer claims are different scientific claims and must not be interpreted interchangeably.
A30: Weak-split policy | B30: Weak split results are allowed only as inflation demonstrations and diagnostic contrast. They are not confirmatory evidence.
A33: Governance additions | B33: Claim_Ledger enforces claim discipline. AI_Usage_Log supports tool transparency and human verification traceability. Ethics_Governance_Notes supports risk/mitigation accountability.
A36: Workflow | B36: Master_Experiments + Data_Selection_Design + Grouping_Strategy_Map -> Run_Log -> Decision_Log -> Confirmatory_Set -> Claim_Ledger/AI_Usage_Log/Ethics_Governance_Notes -> Thesis_Map -> Dashboard.
A39: This workbook is aligned to thesis method-choice/method-application workflow, data-slice/grouping governance, and leakage-aware reporting requirements.
A45: Schema_Metadata_Key | B45: Value
A46: workbook_schema_version | B46: workbook-v1
A47: compiled_manifest_schema_version | B47: compiled-manifest-v1
A48: artifact_schema_version | B48: artifact-v1
A49: workbook_writeback_schema_version | B49: workbook-writeback-v1
A50: summary_result_schema_version | B50: summary-result-v1
A52: Generated by create_thesis_experiment_workbook.py (v2)

Sheet Master_Experiments
A1: Experiment_ID | B1: Short_Title | C1: Category | D1: Evidential_Role | E1: Stage | F1: Priority | G1: Decision_Supported | H1: Exact_Question | I1: Hypothesis_or_Expectation | J1: Manipulated_Factor | K1: Held_Constant_Controls | L1: Dataset_Scope | M1: Target_Definition | N1: Split_Logic | O1: Leakage_Risk | P1: Leakage_Control | Q1: Models_Compared | R1: Primary_Metric | S1: Secondary_Metrics | T1: Robustness_Checks | U1: Decision_Criterion | V1: Success_Pattern | W1: Failure_or_Warning_Pattern | X1: Threats_to_Validity | Y1: Reporting_Destination | Z1: Interpretation_Boundary | AA1: Status | AB1: Owner | AC1: Outcome_Summary | AD1: Decision_Taken | AE1: Notes | AF1: Experiment_Ready
A2: E01 | B2: Target granularity experiment | C2: Target-definition | D2: Secondary decision-support | E2: Stage 1 - Target lock | F2: High | G2: Final target lock | H2: Should the thesis use fine-grained emotion labels, three-class coarse affect, or binary valence-like labels? | I2: coarse_affect likely balances construct validity, class balance, and learnability. | J2: Target definition | K2: Dataset index version, train-only fitting policy, metric definitions, seed policy, artifact schema. | L2: Internal repeated-session BAS2 dataset (sub-001 and sub-002) unless explicitly external. | M2: fine emotion vs coarse_affect vs binary valence-like | N2: within_subject_loso_session for primary comparison; frozen transfer as secondary check | O2: Performance inflation if split logic or fit scope leaks train/test information. | P2: Predefined split manifests, train-only fitting, frozen transfer where applicable, no test-driven tuning. | Q2: ridge baseline unless model family is manipulated. | R2: Balanced accuracy | S2: Macro-F1; class-wise recall; accuracy | T2: Fold-level checks and stress controls where relevant. | U2: Prefer target balancing construct validity, class balance, sample sufficiency, and learnability under claim-matched evaluation. | V2: Stable claim-consistent performance without leakage indicators. | W2: Weak-split inflation, instability, class collapse, or directionally inconsistent evidence. | X2: Class imbalance, sample limits, domain shift, and model/split sensitivity. | Y2: Chapter 3 Method choice | Z2: Interpret only under stated split logic/evidence tier; no causal or localization claims. | AA2: Planned | AB2: Khaled (thesis author) | AF2: =IF($AA2="Dropped","N/A",IF(AND($H2<>"",$J2<>"",$K2<>"",$M2<>"",$N2<>"",$P2<>"",$R2<>"",$U2<>"",$V2<>"",$W2<>"",$Z2<>"",$Y2<>""),"READY","INCOMPLETE"))
A3: E02 | B3: Task pooling experiment | C3: Target-definition | D3: Secondary decision-support | E3: Stage 1 - Target lock | F3: Medium | G3: Task pooling policy | H3: Should the main target be learned across all tasks together, or separately by task? | I3: Evaluate under leakage-aware claim-matched split logic before interpretation. | J3: Pooling strategy by task | K3: Dataset index version, train-only fitting policy, metric definitions, seed policy, artifact schema. | L3: Internal repeated-session BAS2 dataset (sub-001 and sub-002) unless explicitly external. | M3: coarse_affect unless this experiment manipulates target granularity. | N3: Claim-matched leakage-safe split strategy. | O3: Performance inflation if split logic or fit scope leaks train/test information. | P3: Predefined split manifests, train-only fitting, frozen transfer where applicable, no test-driven tuning. | Q3: ridge baseline unless model family is manipulated. | R3: Balanced accuracy | S3: Macro-F1; class-wise recall; accuracy | T3: Fold-level checks and stress controls where relevant. | U3: Pre-specified criterion recorded before interpretation. | V3: Stable claim-consistent performance without leakage indicators. | W3: Weak-split inflation, instability, class collapse, or directionally inconsistent evidence. | X3: Class imbalance, sample limits, domain shift, and model/split sensitivity. | Y3: Chapter 3 Method choice | Z3: Interpret only under stated split logic/evidence tier; no causal or localization claims. | AA3: Planned | AB3: Khaled (thesis author) | AF3: =IF($AA3="Dropped","N/A",IF(AND($H3<>"",$J3<>"",$K3<>"",$M3<>"",$N3<>"",$P3<>"",$R3<>"",$U3<>"",$V3<>"",$W3<>"",$Z3<>"",$Y3<>""),"READY","INCOMPLETE"))
A4: E03 | B4: Modality pooling experiment | C4: Target-definition | D4: Secondary decision-support | E4: Stage 1 - Target lock | F4: Medium | G4: Modality pooling policy | H4: Should audio, video, and audiovisual conditions be pooled or modeled separately? | I4: Evaluate under leakage-aware claim-matched split logic before interpretation. | J4: Pooling strategy by modality | K4: Dataset index version, train-only fitting policy, metric definitions, seed policy, artifact schema. | L4: Internal repeated-session BAS2 dataset (sub-001 and sub-002) unless explicitly external. | M4: coarse_affect unless this experiment manipulates target granularity. | N4: Claim-matched leakage-safe split strategy. | O4: Performance inflation if split logic or fit scope leaks train/test information. | P4: Predefined split manifests, train-only fitting, frozen transfer where applicable, no test-driven tuning. | Q4: ridge baseline unless model family is manipulated. | R4: Balanced accuracy | S4: Macro-F1; class-wise recall; accuracy | T4: Fold-level checks and stress controls where relevant. | U4: Pre-specified criterion recorded before interpretation. | V4: Stable claim-consistent performance without leakage indicators. | W4: Weak-split inflation, instability, class collapse, or directionally inconsistent evidence. | X4: Class imbalance, sample limits, domain shift, and model/split sensitivity. | Y4: Chapter 3 Method choice | Z4: Interpret only under stated split logic/evidence tier; no causal or localization claims. | AA4: Planned | AB4: Khaled (thesis author) | AF4: =IF($AA4="Dropped","N/A",IF(AND($H4<>"",$J4<>"",$K4<>"",$M4<>"",$N4<>"",$P4<>"",$R4<>"",$U4<>"",$V4<>"",$W4<>"",$Z4<>"",$Y4<>""),"READY","INCOMPLETE"))
A5: E04 | B5: Split-strength stress test | C5: Split-design | D5: Secondary decision-support | E5: Stage 2 - Split lock | F5: High | G5: Primary split policy | H5: How much do conclusions change under weaker split strategies compared with session-held-out evaluation? | I5: Evaluate under leakage-aware claim-matched split logic before interpretation. | J5: Split logic | K5: Dataset index version, train-only fitting policy, metric definitions, seed policy, artifact schema. | L5: Internal repeated-session BAS2 dataset (sub-001 and sub-002) unless explicitly external. | M5: coarse_affect unless this experiment manipulates target granularity. | N5: record-wise random split vs weaker grouped split vs within-person leave-one-session-out | O5: High under weak splits | P5: Predefined split manifests, train-only fitting, frozen transfer where applicable, no test-driven tuning. | Q5: ridge baseline unless model family is manipulated. | R5: Balanced accuracy | S5: Macro-F1; class-wise recall; accuracy | T5: Fold-level checks and stress controls where relevant. | U5: Retain strictest split matching claim; weaker splits only as inflation/leakage demonstrations. | V5: Stable claim-consistent performance without leakage indicators. | W5: Weak-split inflation, instability, class collapse, or directionally inconsistent evidence. | X5: Class imbalance, sample limits, domain shift, and model/split sensitivity. | Y5: Chapter 3 Method choice | Z5: Interpret only under stated split logic/evidence tier; no causal or localization claims. | AA5: Planned | AB5: Khaled (thesis author) | AF5: =IF($AA5="Dropped","N/A",IF(AND($H5<>"",$J5<>"",$K5<>"",$M5<>"",$N5<>"",$P5<>"",$R5<>"",$U5<>"",$V5<>"",$W5<>"",$Z5<>"",$Y5<>""),"READY","INCOMPLETE"))
A6: E05 | B6: Cross-person transfer design | C6: Split-design | D6: Secondary decision-support | E6: Stage 2 - Split lock | F6: High | G6: Cross-person transfer framing | H6: How should cross-person generalization be framed and evaluated? | I6: Evaluate under leakage-aware claim-matched split logic before interpretation. | J6: Transfer protocol | K6: Dataset index version, train-only fitting policy, metric definitions, seed policy, artifact schema. | L6: Internal repeated-session BAS2 dataset (sub-001 and sub-002) unless explicitly external. | M6: coarse_affect unless this experiment manipulates target granularity. | N6: frozen train-on-A/test-on-B and reverse direction | O6: Performance inflation if split logic or fit scope leaks train/test information. | P6: Fit only on train subject; no test subject re-fit/re-tune | Q6: ridge baseline unless model family is manipulated. | R6: Balanced accuracy | S6: Macro-F1; class-wise recall; accuracy | T6: Fold-level checks and stress controls where relevant. | U6: Keep frozen directional transfer as clean cross-case test. | V6: Stable claim-consistent performance without leakage indicators. | W6: Weak-split inflation, instability, class collapse, or directionally inconsistent evidence. | X6: Class imbalance, sample limits, domain shift, and model/split sensitivity. | Y6: Chapter 3 Method choice | Z6: Transfer evidence under domain shift, not population-level generalization. | AA6: Planned | AB6: Khaled (thesis author) | AF6: =IF($AA6="Dropped","N/A",IF(AND($H6<>"",$J6<>"",$K6<>"",$M6<>"",$N6<>"",$P6<>"",$R6<>"",$U6<>"",$V6<>"",$W6<>"",$Z6<>"",$Y6<>""),"READY","INCOMPLETE"))
A7: E06 | B7: Linear model family comparison | C7: Model-comparison | D7: Secondary decision-support | E7: Stage 3 - Model lock | F7: High | G7: Model family lock | H7: Which linear model is the most appropriate default: ridge, logistic regression, or linear SVM? | I7: Evaluate under leakage-aware claim-matched split logic before interpretation. | J7: Model family | K7: Dataset index version, train-only fitting policy, metric definitions, seed policy, artifact schema. | L7: Internal repeated-session BAS2 dataset (sub-001 and sub-002) unless explicitly external. | M7: coarse_affect unless this experiment manipulates target granularity. | N7: Claim-matched leakage-safe split strategy. | O7: Performance inflation if split logic or fit scope leaks train/test information. | P7: Predefined split manifests, train-only fitting, frozen transfer where applicable, no test-driven tuning. | Q7: ridge vs logreg vs linearsvc | R7: Balanced accuracy | S7: Macro-F1; class-wise recall; accuracy | T7: Fold-level checks and stress controls where relevant. | U7: Prefer simplest model with comparable predictive performance and better robustness/stability. | V7: Stable claim-consistent performance without leakage indicators. | W7: Weak-split inflation, instability, class collapse, or directionally inconsistent evidence. | X7: Class imbalance, sample limits, domain shift, and model/split sensitivity. | Y7: Chapter 3 Method choice | Z7: Interpret only under stated split logic/evidence tier; no causal or localization claims. | AA7: Planned | AB7: Khaled (thesis author) | AF7: =IF($AA7="Dropped","N/A",IF(AND($H7<>"",$J7<>"",$K7<>"",$M7<>"",$N7<>"",$P7<>"",$R7<>"",$U7<>"",$V7<>"",$W7<>"",$Z7<>"",$Y7<>""),"READY","INCOMPLETE"))
A8: E07 | B8: Class weighting experiment | C8: Model-comparison | D8: Secondary decision-support | E8: Stage 3 - Model lock | F8: Medium | G8: Weighting policy | H8: Does class weighting improve fairness across classes without creating instability? | I8: Evaluate under leakage-aware claim-matched split logic before interpretation. | J8: Weighting strategy | K8: Dataset index version, train-only fitting policy, metric definitions, seed policy, artifact schema. | L8: Internal repeated-session BAS2 dataset (sub-001 and sub-002) unless explicitly external. | M8: coarse_affect unless this experiment manipulates target granularity. | N8: Claim-matched leakage-safe split strategy. | O8: Performance inflation if split logic or fit scope leaks train/test information. | P8: Predefined split manifests, train-only fitting, frozen transfer where applicable, no test-driven tuning. | Q8: ridge baseline unless model family is manipulated. | R8: Balanced accuracy | S8: Macro-F1; class-wise recall; accuracy | T8: Fold-level checks and stress controls where relevant. | U8: Pre-specified criterion recorded before interpretation. | V8: Stable claim-consistent performance without leakage indicators. | W8: Weak-split inflation, instability, class collapse, or directionally inconsistent evidence. | X8: Class imbalance, sample limits, domain shift, and model/split sensitivity. | Y8: Chapter 3 Method choice | Z8: Interpret only under stated split logic/evidence tier; no causal or localization claims. | AA8: Planned | AB8: Khaled (thesis author) | AF8: =IF($AA8="Dropped","N/A",IF(AND($H8<>"",$J8<>"",$K8<>"",$M8<>"",$N8<>"",$P8<>"",$R8<>"",$U8<>"",$V8<>"",$W8<>"",$Z8<>"",$Y8<>""),"READY","INCOMPLETE"))
A9: E08 | B9: Hyperparameter strategy experiment | C9: Model-comparison | D9: Secondary decision-support | E9: Stage 3 - Model lock | F9: Medium | G9: Tuning policy | H9: Are fixed conservative hyperparameters sufficient, or does light nested tuning materially improve results? | I9: Evaluate under leakage-aware claim-matched split logic before interpretation. | J9: Tuning strategy | K9: Dataset index version, train-only fitting policy, metric definitions, seed policy, artifact schema. | L9: Internal repeated-session BAS2 dataset (sub-001 and sub-002) unless explicitly external. | M9: coarse_affect unless this experiment manipulates target granularity. | N9: Claim-matched leakage-safe split strategy. | O9: Performance inflation if split logic or fit scope leaks train/test information. | P9: Predefined split manifests, train-only fitting, frozen transfer where applicable, no test-driven tuning. | Q9: ridge baseline unless model family is manipulated. | R9: Balanced accuracy | S9: Macro-F1; class-wise recall; accuracy | T9: Fold-level checks and stress controls where relevant. | U9: Keep fixed settings unless nested tuning yields a clear and stable gain. | V9: Stable claim-consistent performance without leakage indicators. | W9: Weak-split inflation, instability, class collapse, or directionally inconsistent evidence. | X9: Class imbalance, sample limits, domain shift, and model/split sensitivity. | Y9: Chapter 3 Method choice | Z9: Interpret only under stated split logic/evidence tier; no causal or localization claims. | AA9: Planned | AB9: Khaled (thesis author) | AF9: =IF($AA9="Dropped","N/A",IF(AND($H9<>"",$J9<>"",$K9<>"",$M9<>"",$N9<>"",$P9<>"",$R9<>"",$U9<>"",$V9<>"",$W9<>"",$Z9<>"",$Y9<>""),"READY","INCOMPLETE"))
A10: E09 | B10: Whole-brain versus ROI experiment | C10: Preprocessing-feature | D10: Secondary decision-support | E10: Stage 4 - Feature/preprocessing lock | F10: Medium | G10: Feature representation lock | H10: Should the primary representation remain whole-brain masked voxels or use theory-justified ROIs? | I10: Evaluate under leakage-aware claim-matched split logic before interpretation. | J10: Feature space | K10: Dataset index version, train-only fitting policy, metric definitions, seed policy, artifact schema. | L10: Internal repeated-session BAS2 dataset (sub-001 and sub-002) unless explicitly external. | M10: coarse_affect unless this experiment manipulates target granularity. | N10: Claim-matched leakage-safe split strategy. | O10: Performance inflation if split logic or fit scope leaks train/test information. | P10: Predefined split manifests, train-only fitting, frozen transfer where applicable, no test-driven tuning. | Q10: ridge baseline unless model family is manipulated. | R10: Balanced accuracy | S10: Macro-F1; class-wise recall; accuracy | T10: Fold-level checks and stress controls where relevant. | U10: Pre-specified criterion recorded before interpretation. | V10: Stable claim-consistent performance without leakage indicators. | W10: Weak-split inflation, instability, class collapse, or directionally inconsistent evidence. | X10: Class imbalance, sample limits, domain shift, and model/split sensitivity. | Y10: Chapter 3 Method choice | Z10: Interpret only under stated split logic/evidence tier; no causal or localization claims. | AA10: Planned | AB10: Khaled (thesis author) | AF10: =IF($AA10="Dropped","N/A",IF(AND($H10<>"",$J10<>"",$K10<>"",$M10<>"",$N10<>"",$P10<>"",$R10<>"",$U10<>"",$V10<>"",$W10<>"",$Z10<>"",$Y10<>""),"READY","INCOMPLETE"))
A11: E10 | B11: Dimensionality reduction experiment | C11: Preprocessing-feature | D11: Secondary decision-support | E11: Stage 4 - Feature/preprocessing lock | F11: Medium | G11: Feature reduction policy | H11: Does unsupervised dimensionality reduction improve performance or stability enough to justify added complexity? | I11: Evaluate under leakage-aware claim-matched split logic before interpretation. | J11: Feature reduction strategy | K11: Dataset index version, train-only fitting policy, metric definitions, seed policy, artifact schema. | L11: Internal repeated-session BAS2 dataset (sub-001 and sub-002) unless explicitly external. | M11: coarse_affect unless this experiment manipulates target granularity. | N11: Claim-matched leakage-safe split strategy. | O11: Performance inflation if split logic or fit scope leaks train/test information. | P11: Predefined split manifests, train-only fitting, frozen transfer where applicable, no test-driven tuning. | Q11: ridge baseline unless model family is manipulated. | R11: Balanced accuracy | S11: Macro-F1; class-wise recall; accuracy | T11: Fold-level checks and stress controls where relevant. | U11: Pre-specified criterion recorded before interpretation. | V11: Stable claim-consistent performance without leakage indicators. | W11: Weak-split inflation, instability, class collapse, or directionally inconsistent evidence. | X11: Class imbalance, sample limits, domain shift, and model/split sensitivity. | Y11: Chapter 3 Method choice | Z11: Interpret only under stated split logic/evidence tier; no causal or localization claims. | AA11: Planned | AB11: Khaled (thesis author) | AF11: =IF($AA11="Dropped","N/A",IF(AND($H11<>"",$J11<>"",$K11<>"",$M11<>"",$N11<>"",$P11<>"",$R11<>"",$U11<>"",$V11<>"",$W11<>"",$Z11<>"",$Y11<>""),"READY","INCOMPLETE"))
A12: E11 | B12: Scaling and normalization experiment | C12: Preprocessing-feature | D12: Secondary decision-support | E12: Stage 4 - Feature/preprocessing lock | F12: Medium | G12: Scaling policy lock | H12: How sensitive are the results to scaling strategy? | I12: Evaluate under leakage-aware claim-matched split logic before interpretation. | J12: Scaling policy | K12: Dataset index version, train-only fitting policy, metric definitions, seed policy, artifact schema. | L12: Internal repeated-session BAS2 dataset (sub-001 and sub-002) unless explicitly external. | M12: coarse_affect unless this experiment manipulates target granularity. | N12: Claim-matched leakage-safe split strategy. | O12: Performance inflation if split logic or fit scope leaks train/test information. | P12: Predefined split manifests, train-only fitting, frozen transfer where applicable, no test-driven tuning. | Q12: ridge baseline unless model family is manipulated. | R12: Balanced accuracy | S12: Macro-F1; class-wise recall; accuracy | T12: Fold-level checks and stress controls where relevant. | U12: Pre-specified criterion recorded before interpretation. | V12: Stable claim-consistent performance without leakage indicators. | W12: Weak-split inflation, instability, class collapse, or directionally inconsistent evidence. | X12: Class imbalance, sample limits, domain shift, and model/split sensitivity. | Y12: Chapter 3 Method choice | Z12: Interpret only under stated split logic/evidence tier; no causal or localization claims. | AA12: Planned | AB12: Khaled (thesis author) | AF12: =IF($AA12="Dropped","N/A",IF(AND($H12<>"",$J12<>"",$K12<>"",$M12<>"",$N12<>"",$P12<>"",$R12<>"",$U12<>"",$V12<>"",$W12<>"",$Z12<>"",$Y12<>""),"READY","INCOMPLETE"))
A13: E12 | B13: Permutation test experiment | C13: Robustness | D13: Primary-supporting robustness | E13: Stage 6 - Robustness analysis | F13: High | G13: Chance-level distinguishability support | H13: Are the main predictive results distinguishable from chance under the exact same split logic? | I13: Evaluate under leakage-aware claim-matched split logic before interpretation. | J13: Label structure (true vs permuted) | K13: Dataset index version, train-only fitting policy, metric definitions, seed policy, artifact schema. | L13: Internal repeated-session BAS2 dataset (sub-001 and sub-002) unless explicitly external. | M13: coarse_affect unless this experiment manipulates target granularity. | N13: exact confirmatory split logic with train-only permutation | O13: Performance inflation if split logic or fit scope leaks train/test information. | P13: Predefined split manifests, train-only fitting, frozen transfer where applicable, no test-driven tuning. | Q13: ridge baseline unless model family is manipulated. | R13: Balanced accuracy | S13: Empirical p-value; null distribution summary | T13: Fold-level checks and stress controls where relevant. | U13: Pre-specified criterion recorded before interpretation. | V13: Stable claim-consistent performance without leakage indicators. | W13: Weak-split inflation, instability, class collapse, or directionally inconsistent evidence. | X13: Class imbalance, sample limits, domain shift, and model/split sensitivity. | Y13: Chapter 4 Supporting robustness | Z13: Interpret only under stated split logic/evidence tier; no causal or localization claims. | AA13: Planned | AB13: Khaled (thesis author) | AF13: =IF($AA13="Dropped","N/A",IF(AND($H13<>"",$J13<>"",$K13<>"",$M13<>"",$N13<>"",$P13<>"",$R13<>"",$U13<>"",$V13<>"",$W13<>"",$Z13<>"",$Y13<>""),"READY","INCOMPLETE"))
... A20: E19 | B20: External open-source model portability | C20: External exploratory | D20: Exploratory extension | E20: Stage 7 - Exploratory extension | F20: Low | G20: External model portability exploration | H20: Does the relative ranking of reasonable model choices remain similar on external data? | I20: Evaluate under leakage-aware claim-matched split logic before interpretation. | J20: Dataset source with same small model set | K20: Dataset index version, train-only fitting policy, metric definitions, seed policy, artifact schema. | L20: External open-source dataset if available and approved | M20: coarse_affect unless this experiment manipulates target granularity. | N20: Claim-matched leakage-safe split strategy. | O20: Performance inflation if split logic or fit scope leaks train/test information. | P20: Predefined split manifests, train-only fitting, frozen transfer where applicable, no test-driven tuning. | Q20: ridge vs logreg vs linearsvc | R20: Balanced accuracy | S20: Macro-F1; class-wise recall; accuracy | T20: Fold-level checks and stress controls where relevant. | U20: Pre-specified criterion recorded before interpretation. | V20: Stable claim-consistent performance without leakage indicators. | W20: Weak-split inflation, instability, class collapse, or directionally inconsistent evidence. | X20: Class imbalance, sample limits, domain shift, and model/split sensitivity. | Y20: Appendix | Z20: Interpret only under stated split logic/evidence tier; no causal or localization claims. | AA20: Planned | AB20: Khaled (thesis author) | AF20: =IF($AA20="Dropped","N/A",IF(AND($H20<>"",$J20<>"",$K20<>"",$M20<>"",$N20<>"",$P20<>"",$R20<>"",$U20<>"",$V20<>"",$W20<>"",$Z20<>"",$Y20<>""),"READY","INCOMPLETE"))

Sheet Experiment_Definitions
A1: experiment_id | B1: enabled | C1: start_section | D1: end_section | E1: base_artifact_id | F1: target | G1: cv | H1: model | I1: subject | J1: train_subject | K1: test_subject | L1: filter_task | M1: filter_modality | N1: reuse_policy | O1: search_space_id
A2: E16 | B2: No | C2: dataset_selection | D2: evaluation | F2: coarse_affect | G2: within_subject_loso_session | H2: ridge | I2: sub-001 | N2: auto
A3: E17 | B3: No | C3: dataset_selection | D3: evaluation | F3: coarse_affect | G3: frozen_cross_person_transfer | H3: ridge | J3: sub-001 | K3: sub-002 | N3: auto

Sheet Search_Spaces
A1: Search Space Definitions
A2: search_space_id | B2: enabled | C2: optimization_mode | D2: parameter_name | E2: parameter_values | F2: parameter_scope | G2: objective_metric | H2: max_trials | I2: notes
A3: SS01 | B3: No | C3: deterministic_grid | D3: model | E3: ridge|logreg|linearsvc | F3: parameter | G3: balanced_accuracy | I3: Example model-family search.
A4: SS01 | B4: No | C4: deterministic_grid | D4: start_section | E4: dataset_selection|feature_matrix_load | F4: segment | G4: balanced_accuracy | I4: Example section-start search.

Sheet Study_Design
A1: Study Design (Factorial and Custom Matrices)
A2: study_id | B2: study_name | C2: enabled | D2: study_type | E2: intent | F2: question | G2: generalization_claim | H2: start_section | I2: end_section | J2: base_artifact_id | K2: primary_metric | L2: secondary_metrics | M2: cv_scheme | N2: nested_cv | O2: external_validation_planned | P2: blocking_strategy | Q2: randomization_strategy | R2: replication_mode | S2: replication_strategy | T2: num_repeats | U2: random_seed_policy | V2: stopping_rule | W2: notes
A3: S01 | B3: Example full factorial study | C3: No | D3: full_factorial | E3: exploratory | F3: How do model and task filter settings change balanced accuracy? | G3: Within-dataset transfer across held-out sessions only. | H3: dataset_selection | I3: evaluation | K3: balanced_accuracy | L3: macro_f1|accuracy | M3: within_subject_loso_session | N3: No | O3: No | P3: none | Q3: fixed_order | R3: fixed_repeats | S3: fixed_repeats | T3: 1 | U3: fixed | V3: Complete all planned design cells.

Sheet Study_Rigor_Checklist
A1: Study Rigor Checklist
A2: study_id | B2: leakage_risk_reviewed | C2: deployment_boundary_defined | D2: unit_of_analysis_defined | E2: data_hierarchy_defined | F2: missing_data_plan | G2: class_imbalance_plan | H2: subgroup_plan | I2: fairness_or_applicability_notes | J2: reporting_checklist_completed | K2: risk_of_bias_reviewed | L2: confirmatory_lock_applied | M2: analysis_notes

Sheet Analysis_Plan
A1: Analysis Plan
A2: study_id | B2: primary_contrast | C2: secondary_contrasts | D2: aggregation_level | E2: uncertainty_method | F2: multiplicity_handling | G2: interaction_reporting_policy | H2: interpretation_rules | I2: notes

Sheet Factors
A1: Factor Definitions
A2: study_id | B2: factor_name | C2: section_name | D2: parameter_path | E2: factor_type | F2: levels
A3: S01 | B3: model | D3: model | E3: categorical | F3: ridge|logreg
A4: S01 | B4: filter_task | D4: filter_task | E4: categorical | F4: passive|emo

Sheet Fixed_Controls
A1: Fixed Controls
A2: study_id | B2: parameter_path | C2: value

Sheet Constraints
A1: Invalid Combination Constraints
A2: study_id | B2: if_factor | C2: if_level | D2: disallow_factor | E2: disallow_level | F2: reason

Sheet Blocking_and_Replication
A1: Blocking and Replication
A2: study_id | B2: block_type | C2: block_value | D2: repeat_id | E2: seed

Sheet Generated_Design_Matrix
A1: Generated Design Matrix (Machine-managed)
A2: study_id | B2: trial_id | C2: cell_id | D2: factor_settings_json | E2: start_section | F2: end_section | G2: base_artifact_id | H2: resolved_params_json | I2: status

Sheet Effect_Summaries
A1: Effect Summaries (Descriptive)
A2: study_id | B2: summary_type | C2: summary_key | D2: factor_level_key | E2: interaction_key | F2: primary_metric_name | G2: mean_primary_metric_value | H2: best_primary_metric_value | I2: best_trial_id | J2: notes

Sheet Artifact_Registry
A1: Workbook Artifact Registry Snapshot
A2: artifact_id | B2: artifact_type | C2: run_id | D2: status | E2: created_at | F2: path | G2: upstream_artifact_ids | H2: config_hash | I2: code_ref | J2: notes
J3: Optional workbook mirror of machine registry for audit snapshots.

Sheet Fixed_Configs
A1: Fixed Configurations and Locks
A2: config_key | B2: config_value | C2: scope | D2: locked | E2: owner | F2: last_updated | G2: notes
A3: default_target | B3: coarse_affect | C3: global | D3: No | E3: Khaled | G3: Machine-readable defaults for execution templates.
A4: default_model | B4: ridge | C4: global | D4: No | E4: Khaled

Sheet Objectives
A1: Program Objectives
A2: objective_id | B2: objective_text | C2: stage | D2: linked_experiment_id | E2: primary_metric | F2: success_criterion | G2: status | H2: notes
A3: OBJ01 | B3: Lock target definition under leakage-aware evaluation. | C3: Stage 1 - Target lock | D3: E01 | E3: balanced_accuracy | F3: Decision D01 locked with pre-registered rationale. | G3: Planned

Sheet Machine_Status
A1: Machine Status and Environment
A2: machine_id | B2: hostname | C2: environment_name | D2: python_version | E2: gpu | F2: status | G2: last_checked | H2: notes
A3: M01 | C3: thesis-dev | F3: Monitoring | H3: Track execution environment snapshots used for thesis runs.

Sheet Trial_Results
A1: Trial Results (Machine-managed)
A2: trial_id | B2: experiment_id | C2: run_id | D2: status | E2: primary_metric_name | F2: primary_metric_value | G2: report_path | H2: metrics_path | I2: artifact_bundle | J2: notes | K2: study_id | L2: cell_id | M2: factor_settings_json | N2: resolved_params_json

Sheet Summary_Outputs
A1: Machine Summary Outputs (Best Runs and Patterns)
A2: summary_type | B2: summary_key | C2: primary_metric_name | D2: primary_metric_value | E2: run_id | F2: experiment_id | G2: start_section | H2: end_section | I2: model | J2: cv | K2: target | L2: xai_method | M2: report_path | N2: notes

Sheet Data_Selection_Design
A1: Data_Slice_ID | B1: Slice_Name | C1: Purpose | D1: Subject_Scope | E1: Session_Scope | F1: Time_Window | G1: Task_Scope | H1: Modality_Scope | I1: Target_Type | J1: Label_Set | K1: Inclusion_Rule | L1: Exclusion_Rule | M1: Class_Balance_Policy | N1: Minimum_Samples_Rule | O1: Leakage_Risk | P1: Valid_Use_Case | Q1: Thesis_Use | R1: Notes
A2: DS01 | B2: All subjects, all sessions, pooled task, pooled modality, coarse_affect | C2: Global baseline for target/split/model method-choice comparisons. | D2: all_subjects | E2: all_sessions | F2: full_study_window | G2: pooled_all_tasks | H2: pooled_all_modalities | I2: coarse_affect | J2: coarse_affect | K2: All QC-passed repeated-session beta maps with valid labels. | L2: Drop failed-preprocessing rows and missing targets. | M2: as_is | N2: Prefer >=20 per class before claim-level interpretation. | O2: medium | P2: method_choice | Q2: method_choice
A3: DS02 | B3: Subject-specific pooled-task pooled-modality | C3: Primary within-person held-out-session claim support. | D3: single_subject | E3: held_out_session | F3: full_study_window | G3: pooled_all_tasks | H3: pooled_all_modalities | I3: coarse_affect | J3: coarse_affect | K3: One subject at a time with all eligible sessions. | L3: No cross-subject pooling inside fold-level fit. | M3: weighted_only | N3: Per-class floor checked per subject. | O3: low | P3: confirmatory_within_person | Q3: main_confirmatory | R3: Matches held-out-session inference boundary.
A4: DS03 | B4: Task-specific pooled-modality | C4: Task pooling vs task-specific method-choice and diagnostics. | D4: all_subjects | E4: all_sessions | F4: full_study_window | G4: task_specific_other | H4: pooled_all_modalities | I4: coarse_affect | J4: coarse_affect by task | K4: Restrict each run to one task family. | L4: Exclude off-task records for that run. | M4: as_is | N4: Minimum counts checked per task-specific slice. | O4: medium | P4: method_choice | Q4: method_choice
A5: DS04 | B5: Modality-specific pooled-task | C5: Modality pooling vs modality-specific method-choice checks. | D5: all_subjects | E5: all_sessions | F5: full_study_window | G5: pooled_all_tasks | H5: audio_only | I5: coarse_affect | J5: coarse_affect | K5: One modality family per run (audio/video/audiovisual variants). | L5: Exclude other modalities in each modality-specific run. | M5: as_is | N5: Check sample sufficiency per modality variant. | O5: medium | P5: method_choice | Q5: method_choice | R5: Seed modality is audio_only; clone row for other modalities.
A6: DS05 | B6: Subject-specific task x modality subset | C6: Fine-grained diagnostic sensitivity slices. | D6: single_subject | E6: all_sessions | F6: full_study_window | G6: task_specific_other | H6: audiovisual_only | I6: coarse_affect | J6: coarse_affect | K6: Single subject + selected task + selected modality combination. | L6: Exclude all records outside the chosen intersection. | M6: min_count_threshold | N6: Hard floor required before reporting. | O6: high | P6: diagnostic_only | Q6: discussion_limitations
A7: DS06 | B7: Early sessions only | C7: Temporal drift checks and early-to-late transfer design. | D7: all_subjects | E7: early_only | F7: early_window | G7: pooled_all_tasks | H7: pooled_all_modalities | I7: coarse_affect | J7: coarse_affect | K7: Use sessions pre-registered as early window. | L7: Exclude late-window sessions. | M7: as_is | N7: Check class floor by temporal window. | O7: medium | P7: robustness_support | Q7: supporting_robustness
A8: DS07 | B8: Late sessions only | C8: Temporal drift checks and early-to-late transfer design. | D8: all_subjects | E8: late_only | F8: late_window | G8: pooled_all_tasks | H8: pooled_all_modalities | I8: coarse_affect | J8: coarse_affect | K8: Use sessions pre-registered as late window. | L8: Exclude early-window sessions. | M8: as_is | N8: Check class floor by temporal window. | O8: medium | P8: robustness_support | Q8: supporting_robustness
A9: DS08 | B9: Balanced subset only | C9: Imbalance-aware sensitivity diagnostics. | D9: all_subjects | E9: all_sessions | F9: full_study_window | G9: pooled_all_tasks | H9: pooled_all_modalities | I9: coarse_affect | J9: coarse_affect | K9: Only include rows passing balancing policy. | L9: Exclude classes below predefined minimum count floor. | M9: balanced_subset | N9: Set explicit class floor in analysis config. | O9: low | P9: robustness_support | Q9: supporting_robustness | R9: Do not replace confirmatory as-is evidence with this slice.

Sheet Grouping_Strategy_Map
A1: Grouping_Strategy_ID | B1: Strategy_Name | C1: Split_Family | D1: Train_Group_Unit | E1: Test_Group_Unit | F1: Grouping_Level | G1: Train_Rule | H1: Test_Rule | I1: Leakage_Safeguard | J1: Suitable_For | K1: Not_Suitable_For | L1: Interpretation_Boundary | M1: Typical_Experiments | N1: Thesis_Section | O1: Notes
A2: GS01 | B2: within-subject LOSO-session | C2: within_subject | D2: subject_session | E2: session | F2: within_subject | G2: Per subject: train on all but one session. | H2: Per subject: test on held-out session. | I2: No held-out session rows in any train-side fit/tune stage. | J2: confirmatory_within_person | K2: confirmatory_cross_person_transfer | L2: Supports within-person held-out-session claim only. | M2: E04,E16 | N2: Chapter 4 Main results
A3: GS02 | B3: pooled-task within-subject LOSO-session | C3: within_subject | D3: subject_session | E3: session | F3: within_subject | G3: Within each subject, pool tasks and hold out one session. | H3: Evaluate on held-out session with pooled task scope. | I3: No test-session information in pooled train transforms. | J3: confirmatory_within_person | K3: confirmatory_cross_person_transfer | L3: Within-person conclusion under pooled task policy. | M3: E02,E16 | N3: Chapter 3 Method choice
A4: GS03 | B4: task-specific within-subject LOSO-session | C4: within_subject | D4: subject_session | E4: session | F4: task_level | G4: Within each subject/task, hold out one session. | H4: Test on same-task held-out session. | I4: Task-specific split manifests and train-only preprocessing. | J4: method_choice | K4: confirmatory_cross_person_transfer | L4: Task-conditioned within-person evidence only. | M4: E02,E15 | N4: Chapter 3 Method choice
A5: GS04 | B5: modality-specific within-subject LOSO-session | C5: within_subject | D5: subject_session | E5: session | F5: modality_level | G5: Within each subject/modality, hold out one session. | H5: Test on same-modality held-out session. | I5: Modality-specific fold manifests with strict train-only fit. | J5: method_choice | K5: confirmatory_cross_person_transfer | L5: Modality-conditioned within-person evidence only. | M5: E03,E15 | N5: Chapter 3 Method choice
A6: GS05 | B6: early-train late-test | C6: temporal | D6: session | E6: session | F6: session_level | G6: Train on pre-defined early sessions. | H6: Test on disjoint late sessions. | I6: Fixed temporal boundary and no late-session tuning. | J6: robustness_support | K6: confirmatory_within_person | L6: Temporal transfer sensitivity, not the primary confirmatory claim. | M6: E04,E15 | N6: Chapter 4 Supporting robustness
A7: GS06 | B7: frozen cross-person transfer A->B | C7: cross_person | D7: subject | E7: subject | F7: across_subject | G7: Fit on subject A only (frozen pipeline). | H7: Evaluate on subject B without refit/re-tune. | I7: No test-subject fitting; strict direction lock. | J7: confirmatory_cross_person_transfer | K7: confirmatory_within_person | L7: Directional transfer under domain shift only. | M7: E05,E17 | N7: Chapter 4 Main results
A8: GS07 | B8: frozen cross-person transfer B->A | C8: cross_person | D8: subject | E8: subject | F8: across_subject | G8: Fit on subject B only (frozen pipeline). | H8: Evaluate on subject A without refit/re-tune. | I8: No test-subject fitting; strict direction lock. | J8: confirmatory_cross_person_transfer | K8: confirmatory_within_person | L8: Directional transfer under domain shift only. | M8: E05,E17 | N8: Chapter 4 Main results
A9: GS08 | B9: weak split inflation demo | C9: weak_split_demo | D9: custom_group | E9: custom_group | F9: mixed_level | G9: Use intentionally weaker split variant for contrast. | H9: Evaluate inflation magnitude vs strict split. | I9: Tag as weak split and exclude from confirmatory claims. | J9: weak_split_demo_only | K9: confirmatory_within_person | L9: Inflation demonstration only; non-confirmatory. | M9: E04 | N9: Chapter 3 Method choice | O9: Permitted only as cautionary demonstration.
A10: GS09 | B10: task x modality diagnostic split | C10: diagnostic | D10: task_modality | E10: task_modality | F10: task_modality_level | G10: Train within selected task/modality intersections. | H10: Test on matched or held-out intersections per protocol. | I10: Pre-registered intersection mapping and no adaptive relabeling. | J10: diagnostic_only | K10: confirmatory_within_person | L10: Diagnostic sensitivity only; not core evidence. | M10: E15 | N10: Chapter 5 Discussion

Sheet Data_Profile
A1: Data Profile and Imbalance Diagnostics
A3: How to use | B3: Paste exported counts into Count columns (or maintain manually). Formulas compute shares, imbalance flags, and sparsity flags.
A6: Threshold controls | D6: Profile summary
A7: Sparse count threshold | B7: 20 | D7: Total_subject_samples | G7: =SUM(B13:B20)
A8: Mild imbalance ratio (max/min) | B8: 2 | D8: Total_session_samples | G8: =SUM(B25:B34)
A9: Severe imbalance ratio (max/min) | B9: 3 | D9: Total_task_samples | G9: =SUM(B39:B45)
D10: Total_modality_samples | G10: =SUM(B50:B55)
A11: Counts by subject | G11: =SUM(B60:B65)
A12: Subject_ID | B12: Count | C12: Share_of_Block | D12: Flag | E12: Notes | G12: =IFERROR(MAX(B60:B65)/MIN(B60:B65),"")
A13: sub-001 | C13: =IFERROR(B13/SUM($B$13:$B$20),0) | D13: =IF(B13="","",IF(B13<$B$7,"SPARSE","OK")) | G13: =IF(B60="","",IF(OR(MIN(B60:B65)=0,G12>$B$9),"SEVERE_IMBALANCE",IF(G12>$B$8,"MILD_IMBALANCE","BALANCED")))
A14: sub-002 | C14: =IFERROR(B14/SUM($B$13:$B$20),0) | D14: =IF(B14="","",IF(B14<$B$7,"SPARSE","OK"))
A15: sub-003 | C15: =IFERROR(B15/SUM($B$13:$B$20),0) | D15: =IF(B15="","",IF(B15<$B$7,"SPARSE","OK"))
A16: sub-004 | C16: =IFERROR(B16/SUM($B$13:$B$20),0) | D16: =IF(B16="","",IF(B16<$B$7,"SPARSE","OK"))
A17: sub-005 | C17: =IFERROR(B17/SUM($B$13:$B$20),0) | D17: =IF(B17="","",IF(B17<$B$7,"SPARSE","OK"))
A18: sub-006 | C18: =IFERROR(B18/SUM($B$13:$B$20),0) | D18: =IF(B18="","",IF(B18<$B$7,"SPARSE","OK"))
A19: sub-007 | C19: =IFERROR(B19/SUM($B$13:$B$20),0) | D19: =IF(B19="","",IF(B19<$B$7,"SPARSE","OK"))
A20: sub-008 | C20: =IFERROR(B20/SUM($B$13:$B$20),0) | D20: =IF(B20="","",IF(B20<$B$7,"SPARSE","OK"))
A23: Counts by session
A24: Session_ID | B24: Count | C24: Share_of_Block | D24: Flag | E24: Notes
A25: ses-01 | C25: =IFERROR(B25/SUM($B$25:$B$34),0) | D25: =IF(B25="","",IF(B25<$B$7,"SPARSE","OK"))
A26: ses-02 | C26: =IFERROR(B26/SUM($B$25:$B$34),0) | D26: =IF(B26="","",IF(B26<$B$7,"SPARSE","OK"))
A27: ses-03 | C27: =IFERROR(B27/SUM($B$25:$B$34),0) | D27: =IF(B27="","",IF(B27<$B$7,"SPARSE","OK"))
A28: ses-04 | C28: =IFERROR(B28/SUM($B$25:$B$34),0) | D28: =IF(B28="","",IF(B28<$B$7,"SPARSE","OK"))
A29: ses-05 | C29: =IFERROR(B29/SUM($B$25:$B$34),0) | D29: =IF(B29="","",IF(B29<$B$7,"SPARSE","OK"))
A30: ses-06 | C30: =IFERROR(B30/SUM($B$25:$B$34),0) | D30: =IF(B30="","",IF(B30<$B$7,"SPARSE","OK"))
A31: ses-07 | C31: =IFERROR(B31/SUM($B$25:$B$34),0) | D31: =IF(B31="","",IF(B31<$B$7,"SPARSE","OK"))
A32: ses-08 | C32: =IFERROR(B32/SUM($B$25:$B$34),0) | D32: =IF(B32="","",IF(B32<$B$7,"SPARSE","OK"))
A33: ses-09 | C33: =IFERROR(B33/SUM($B$25:$B$34),0) | D33: =IF(B33="","",IF(B33<$B$7,"SPARSE","OK"))
A34: ses-10 | C34: =IFERROR(B34/SUM($B$25:$B$34),0) | D34: =IF(B34="","",IF(B34<$B$7,"SPARSE","OK"))
A37: Counts by task
A38: Task_ID | B38: Count | C38: Share_of_Block | D38: Flag | E38: Notes
A39: pooled_all_tasks | C39: =IFERROR(B39/SUM($B$39:$B$45),0) | D39: =IF(B39="","",IF(B39<$B$7,"SPARSE","OK"))
A40: passive_only | C40: =IFERROR(B40/SUM($B$39:$B$45),0) | D40: =IF(B40="","",IF(B40<$B$7,"SPARSE","OK"))
A41: emo_only | C41: =IFERROR(B41/SUM($B$39:$B$45),0) | D41: =IF(B41="","",IF(B41<$B$7,"SPARSE","OK"))
A42: rating_only | C42: =IFERROR(B42/SUM($B$39:$B$45),0) | D42: =IF(B42="","",IF(B42<$B$7,"SPARSE","OK"))
A43: task_specific_other | C43: =IFERROR(B43/SUM($B$39:$B$45),0) | D43: =IF(B43="","",IF(B43<$B$7,"SPARSE","OK"))
A44: custom_task_1 | C44: =IFERROR(B44/SUM($B$39:$B$45),0) | D44: =IF(B44="","",IF(B44<$B$7,"SPARSE","OK"))
A45: custom_task_2 | C45: =IFERROR(B45/SUM($B$39:$B$45),0) | D45: =IF(B45="","",IF(B45<$B$7,"SPARSE","OK"))
A48: Counts by modality
A49: Modality_ID | B49: Count | C49: Share_of_Block | D49: Flag | E49: Notes
...

Sheet Run_Log
A1: Run_ID | B1: Experiment_ID | C1: Run_Date | D1: Dataset_Name | E1: Data_Subset | F1: Data_Slice_ID | G1: Grouping_Strategy_ID | H1: Code_Commit_or_Version | I1: Config_File_or_Path | J1: Random_Seed | K1: Target | L1: Split_ID_or_Fold_Definition | M1: Train_Group_Rule | N1: Test_Group_Rule | O1: Transfer_Direction | P1: Session_Coverage | Q1: Task_Coverage | R1: Modality_Coverage | S1: Model | T1: Feature_Set | U1: Run_Type | V1: Affects_Frozen_Pipeline | W1: Eligible_for_Method_Decision | X1: Sample_Count | Y1: Class_Counts | Z1: Imbalance_Status | AA1: Leakage_Check_Status | AB1: Primary_Metric_Value | AC1: Secondary_Metric_1 | AD1: Secondary_Metric_2 | AE1: Robustness_Output_Summary | AF1: Result_Summary | AG1: Preliminary_Interpretation | AH1: Reviewed | AI1: Used_in_Thesis | AJ1: Artifact_Path | AK1: Notes

Sheet Decision_Log
A1: Decision_ID | B1: Decision_Topic | C1: Stage | D1: Candidate_Options | E1: Evidence_Experiments | F1: Decision_Criteria | G1: Chosen_Option | H1: Why_Chosen | I1: Why_Not_Others | J1: Risks_or_Tradeoffs | K1: Grounding_Section_or_Source_Packet | L1: Date_Locked | M1: Freeze_Status | N1: Thesis_Use
A2: D01 | B2: Final target choice | C2: Stage 1 - Target lock | D2: fine emotion; coarse_affect; binary valence-like | E2: E01,E02,E03 | F2: Construct validity + class balance + learnability under strict split | G2: To be locked after method-choice evidence review | J2: Tradeoff between construct validity and learnability | K2: To be linked after background/method revision | M2: Open | N2: Chapter 3 method lock feeding Chapter 4 confirmatory analyses
A3: D02 | B3: Final split design | C3: Stage 2 - Split lock | D3: within_subject_loso_session; weaker alternatives for stress testing | E3: E04,E05 | F3: Prefer strictest split matching claim while documenting weak-split inflation | G3: To be locked after split-strength evidence review | J3: Weak split inflation risk | K3: To be linked after method section split rationale update | M3: Open | N3: Defines primary inference logic and leakage controls
A4: D03 | B4: Final model family | C4: Stage 3 - Model lock | D4: ridge; logreg; linearsvc | E4: E06 | F4: Simplicity + robustness + comparable performance | G4: To be locked after model comparison | J4: Complexity vs stability tradeoff | K4: To be linked after model-choice subsection revision | M4: Open | N4: Sets final confirmatory model family
A5: D04 | B5: Final weighting policy | C5: Stage 3 - Model lock | D5: No class weighting; balanced weighting | E5: E07 | F5: Minority-class fairness gain without instability | G5: To be locked after weighting sensitivity | J5: Fairness-stability tension | K5: To be linked after class-imbalance discussion draft | M5: Open | N5: Controls fairness assumptions in final pipeline
A6: D05 | B6: Final tuning policy | C6: Stage 3 - Model lock | D6: Fixed explicit settings; light nested tuning | E6: E08 | F6: Keep fixed unless clear stable gain from tuning | G6: To be locked after tuning strategy review | J6: Overfitting and complexity risk with tuning | K6: To be linked after reproducibility subsection update | M6: Open | N6: Determines model configuration policy
A7: D06 | B7: Final feature representation | C7: Stage 4 - Feature/preprocessing lock | D7: Whole-brain masked voxels; theory-justified ROI | E7: E09,E10 | F7: Validity + stability + complexity tradeoff | G7: To be locked after feature-space evidence review | J7: Representation choice impacts validity and interpretability | K7: To be linked after feature-method section update | M7: Open | N7: Locks final feature representation
A8: D07 | B8: Final scaling policy | C8: Stage 4 - Feature/preprocessing lock | D8: No scaling; standard/robust scaling (train-only) | E8: E11 | F8: Train-only scaling with best stability and simplicity | G8: To be locked after scaling sensitivity | J8: Scaling can alter class boundaries | K8: To be linked after preprocessing subsection revision | M8: Open | N8: Locks preprocessing policy
A9: D08 | B9: Use of external data | C9: Stage 7 - Exploratory extension | D9: No external data; external replication/portability | E9: E18,E19 | F9: External work remains exploratory and non-core | G9: To be decided after confirmatory core completion | J9: Comparability and external validity limits | K9: To be linked after discussion/limitations revision | M9: Open | N9: Controls exploratory external scope and appendix use

Sheet Confirmatory_Set
A1: Experiment_ID | B1: Short_Title | C1: Final_Pipeline_Version | D1: Claim_Supported | E1: Status | F1: Eligible_to_Run | G1: Completed | H1: Required_for_Main_Claim | I1: Ready_for_Chapter_4 | J1: Confirmatory_Eligible | K1: Main_Result_Summary | L1: Robustness_Status
A2: E12 | B2: Permutation test experiment | C2: To be fixed after freeze lock | D2: Chance-distinguishability support | E2: =IFERROR(INDEX(Master_Experiments!$AA:$AA,MATCH($A2,Master_Experiments!$A:$A,0)),"Planned") | F2: =IF(AND($J2="YES",IFERROR(INDEX(Master_Experiments!$AF:$AF,MATCH($A2,Master_Experiments!$A:$A,0)),"INCOMPLETE")="READY"),"YES","NO") | G2: =IF(IFERROR(INDEX(Master_Experiments!$AA:$AA,MATCH($A2,Master_Experiments!$A:$A,0)),"Planned")="Completed","YES","NO") | H2: YES | I2: NO | J2: =IF(AND(COUNTIFS(Decision_Log!$A:$A,"D01",Decision_Log!$M:$M,"Locked")>0,COUNTIFS(Decision_Log!$A:$A,"D02",Decision_Log!$M:$M,"Locked")>0,COUNTIFS(Decision_Log!$A:$A,"D03",Decision_Log!$M:$M,"Locked")>0,COUNTIFS(Decision_Log!$A:$A,"D04",Decision_Log!$M:$M,"Locked")>0,COUNTIFS(Decision_Log!$A:$A,"D05",Decision_Log!$M:$M,"Locked")>0,COUNTIFS(Decision_Log!$A:$A,"D06",Decision_Log!$M:$M,"Locked")>0,COUNTIFS(Decision_Log!$A:$A,"D07",Decision_Log!$M:$M,"Locked")>0),"YES","NO") | K2: =IFERROR(INDEX(Master_Experiments!$AC:$AC,MATCH($A2,Master_Experiments!$A:$A,0)),"") | L2: Planned
A3: E13 | B3: Trivial baseline experiment | C3: To be fixed after freeze lock | D3: Non-trivial predictive value support | E3: =IFERROR(INDEX(Master_Experiments!$AA:$AA,MATCH($A3,Master_Experiments!$A:$A,0)),"Planned") | F3: =IF(AND($J3="YES",IFERROR(INDEX(Master_Experiments!$AF:$AF,MATCH($A3,Master_Experiments!$A:$A,0)),"INCOMPLETE")="READY"),"YES","NO") | G3: =IF(IFERROR(INDEX(Master_Experiments!$AA:$AA,MATCH($A3,Master_Experiments!$A:$A,0)),"Planned")="Completed","YES","NO") | H3: YES | I3: NO | J3: =IF(AND(COUNTIFS(Decision_Log!$A:$A,"D01",Decision_Log!$M:$M,"Locked")>0,COUNTIFS(Decision_Log!$A:$A,"D02",Decision_Log!$M:$M,"Locked")>0,COUNTIFS(Decision_Log!$A:$A,"D03",Decision_Log!$M:$M,"Locked")>0,COUNTIFS(Decision_Log!$A:$A,"D04",Decision_Log!$M:$M,"Locked")>0,COUNTIFS(Decision_Log!$A:$A,"D05",Decision_Log!$M:$M,"Locked")>0,COUNTIFS(Decision_Log!$A:$A,"D06",Decision_Log!$M:$M,"Locked")>0,COUNTIFS(Decision_Log!$A:$A,"D07",Decision_Log!$M:$M,"Locked")>0),"YES","NO") | K3: =IFERROR(INDEX(Master_Experiments!$AC:$AC,MATCH($A3,Master_Experiments!$A:$A,0)),"") | L3: Planned
A4: E14 | B4: Stability of explanation experiment | C4: To be fixed after freeze lock | D4: Model-behavior robustness support | E4: =IFERROR(INDEX(Master_Experiments!$AA:$AA,MATCH($A4,Master_Experiments!$A:$A,0)),"Planned") | F4: =IF(AND($J4="YES",IFERROR(INDEX(Master_Experiments!$AF:$AF,MATCH($A4,Master_Experiments!$A:$A,0)),"INCOMPLETE")="READY"),"YES","NO") | G4: =IF(IFERROR(INDEX(Master_Experiments!$AA:$AA,MATCH($A4,Master_Experiments!$A:$A,0)),"Planned")="Completed","YES","NO") | H4: YES | I4: NO | J4: =IF(AND(COUNTIFS(Decision_Log!$A:$A,"D01",Decision_Log!$M:$M,"Locked")>0,COUNTIFS(Decision_Log!$A:$A,"D02",Decision_Log!$M:$M,"Locked")>0,COUNTIFS(Decision_Log!$A:$A,"D03",Decision_Log!$M:$M,"Locked")>0,COUNTIFS(Decision_Log!$A:$A,"D04",Decision_Log!$M:$M,"Locked")>0,COUNTIFS(Decision_Log!$A:$A,"D05",Decision_Log!$M:$M,"Locked")>0,COUNTIFS(Decision_Log!$A:$A,"D06",Decision_Log!$M:$M,"Locked")>0,COUNTIFS(Decision_Log!$A:$A,"D07",Decision_Log!$M:$M,"Locked")>0),"YES","NO") | K4: =IFERROR(INDEX(Master_Experiments!$AC:$AC,MATCH($A4,Master_Experiments!$A:$A,0)),"") | L4: Planned
A5: E16 | B5: Final within-person confirmatory analysis | C5: To be fixed after freeze lock | D5: Primary within-person claim | E5: =IFERROR(INDEX(Master_Experiments!$AA:$AA,MATCH($A5,Master_Experiments!$A:$A,0)),"Planned") | F5: =IF(AND($J5="YES",IFERROR(INDEX(Master_Experiments!$AF:$AF,MATCH($A5,Master_Experiments!$A:$A,0)),"INCOMPLETE")="READY"),"YES","NO") | G5: =IF(IFERROR(INDEX(Master_Experiments!$AA:$AA,MATCH($A5,Master_Experiments!$A:$A,0)),"Planned")="Completed","YES","NO") | H5: YES | I5: NO | J5: =IF(AND(COUNTIFS(Decision_Log!$A:$A,"D01",Decision_Log!$M:$M,"Locked")>0,COUNTIFS(Decision_Log!$A:$A,"D02",Decision_Log!$M:$M,"Locked")>0,COUNTIFS(Decision_Log!$A:$A,"D03",Decision_Log!$M:$M,"Locked")>0,COUNTIFS(Decision_Log!$A:$A,"D04",Decision_Log!$M:$M,"Locked")>0,COUNTIFS(Decision_Log!$A:$A,"D05",Decision_Log!$M:$M,"Locked")>0,COUNTIFS(Decision_Log!$A:$A,"D06",Decision_Log!$M:$M,"Locked")>0,COUNTIFS(Decision_Log!$A:$A,"D07",Decision_Log!$M:$M,"Locked")>0),"YES","NO") | K5: =IFERROR(INDEX(Master_Experiments!$AC:$AC,MATCH($A5,Master_Experiments!$A:$A,0)),"") | L5: Planned
A6: E17 | B6: Final cross-person transfer analysis | C6: To be fixed after freeze lock | D6: Secondary transfer claim | E6: =IFERROR(INDEX(Master_Experiments!$AA:$AA,MATCH($A6,Master_Experiments!$A:$A,0)),"Planned") | F6: =IF(AND($J6="YES",IFERROR(INDEX(Master_Experiments!$AF:$AF,MATCH($A6,Master_Experiments!$A:$A,0)),"INCOMPLETE")="READY"),"YES","NO") | G6: =IF(IFERROR(INDEX(Master_Experiments!$AA:$AA,MATCH($A6,Master_Experiments!$A:$A,0)),"Planned")="Completed","YES","NO") | H6: YES | I6: NO | J6: =IF(AND(COUNTIFS(Decision_Log!$A:$A,"D01",Decision_Log!$M:$M,"Locked")>0,COUNTIFS(Decision_Log!$A:$A,"D02",Decision_Log!$M:$M,"Locked")>0,COUNTIFS(Decision_Log!$A:$A,"D03",Decision_Log!$M:$M,"Locked")>0,COUNTIFS(Decision_Log!$A:$A,"D04",Decision_Log!$M:$M,"Locked")>0,COUNTIFS(Decision_Log!$A:$A,"D05",Decision_Log!$M:$M,"Locked")>0,COUNTIFS(Decision_Log!$A:$A,"D06",Decision_Log!$M:$M,"Locked")>0,COUNTIFS(Decision_Log!$A:$A,"D07",Decision_Log!$M:$M,"Locked")>0),"YES","NO") | K6: =IFERROR(INDEX(Master_Experiments!$AC:$AC,MATCH($A6,Master_Experiments!$A:$A,0)),"") | L6: Planned

Sheet Thesis_Map
A1: Experiment_ID | B1: Chapter | C1: Section | D1: Purpose_in_Thesis | E1: Main_or_Supporting | F1: Method_Choice_or_Method_Application_or_Discussion | G1: What_Claim_or_Decision_It_Supports | H1: Notes_for_Writing
A2: E01 | B2: Chapter 3 | C2: 3.3 Target definition | D2: Target granularity method choice | E2: Supporting | F2: Method choice | G2: Locks target definition | H2: Reference Decision D01
A3: E02 | B3: Chapter 3 | C3: 3.3 Task strategy | D3: Task pooling method choice | E3: Supporting | F3: Method choice | G3: Task pooling policy
