Workbook
Name List_Experiment_ID: 'Master_Experiments'!$A$2:INDEX('Master_Experiments'!$A:$A,MATCH("zzz",'Master_Experiments'!$A:$A))
Name List_Search_Space_ID: 'Search_Spaces'!$A$3:INDEX('Search_Spaces'!$A:$A,MATCH("zzz",'Search_Spaces'!$A:$A))
Name List_Study_ID: 'Study_Design'!$A$3:INDEX('Study_Design'!$A:$A,MATCH("zzz",'Study_Design'!$A:$A))
Name List_Data_Slice_ID: 'Data_Selection_Design'!$A$2:INDEX('Data_Selection_Design'!$A:$A,MATCH("zzz",'Data_Selection_Design'!$A:$A))
Name List_Grouping_Strategy_ID: 'Grouping_Strategy_Map'!$A$2:INDEX('Grouping_Strategy_Map'!$A:$A,MATCH("zzz",'Grouping_Strategy_Map'!$A:$A))
Name List_Category: 'Dictionary_Validation'!$A$3:$A$9
Name List_Evidential_Role: 'Dictionary_Validation'!$B$3:$B$7
Name List_Stage: 'Dictionary_Validation'!$C$3:$C$9
Name List_Priority: 'Dictionary_Validation'!$D$3:$D$6
Name List_Status: 'Dictionary_Validation'!$E$3:$E$8
Name List_Reporting_Destination: 'Dictionary_Validation'!$F$3:$F$7
Name List_Reviewed: 'Dictionary_Validation'!$G$3:$G$4
Name List_Used_in_Thesis: 'Dictionary_Validation'!$H$3:$H$4
Name List_Freeze_Status: 'Dictionary_Validation'!$I$3:$I$4
Name List_Run_Type: 'Dictionary_Validation'!$J$3:$J$7
Name List_Affects_Frozen_Pipeline: 'Dictionary_Validation'!$K$3:$K$4
Name List_Eligible_for_Method_Decision: 'Dictionary_Validation'!$L$3:$L$4
Name List_Claim_Type: 'Dictionary_Validation'!$M$3:$M$6
Name List_Evidence_Status: 'Dictionary_Validation'!$N$3:$N$5
Name List_Writing_Location: 'Dictionary_Validation'!$O$3:$O$6
Name List_Human_Verification_Status: 'Dictionary_Validation'!$P$3:$P$5
Name List_Ethics_Status: 'Dictionary_Validation'!$Q$3:$Q$5
Name List_Ethics_Topic: 'Dictionary_Validation'!$R$3:$R$8
Name List_Required_for_Main_Claim: 'Dictionary_Validation'!$S$3:$S$4
Name List_Ready_for_Chapter_4: 'Dictionary_Validation'!$T$3:$T$4
Name List_YesNo: 'Dictionary_Validation'!$U$3:$U$4
Name List_Subject_Scope: 'Dictionary_Validation'!$V$3:$V$5
Name List_Session_Scope: 'Dictionary_Validation'!$W$3:$W$7
Name List_Task_Scope: 'Dictionary_Validation'!$X$3:$X$7
Name List_Modality_Scope: 'Dictionary_Validation'!$Y$3:$Y$6
Name List_Class_Balance_Policy: 'Dictionary_Validation'!$Z$3:$Z$6
Name List_Split_Family: 'Dictionary_Validation'!$AA$3:$AA$7
Name List_Imbalance_Status: 'Dictionary_Validation'!$AB$3:$AB$6
Name List_Leakage_Check_Status: 'Dictionary_Validation'!$AC$3:$AC$6
Name List_Thesis_Use_Tag: 'Dictionary_Validation'!$AD$3:$AD$7
Name List_Use_Case: 'Dictionary_Validation'!$AE$3:$AE$9
Name List_Group_Unit: 'Dictionary_Validation'!$AF$3:$AF$9
Name List_Grouping_Level: 'Dictionary_Validation'!$AG$3:$AG$9
Name List_Transfer_Direction: 'Dictionary_Validation'!$AH$3:$AH$7
Name List_Leakage_Risk_Level: 'Dictionary_Validation'!$AI$3:$AI$6
Name List_Target_Type: 'Dictionary_Validation'!$AJ$3:$AJ$6
Name List_Execution_Section: 'Dictionary_Validation'!$AK$3:$AK$9
Name List_Reuse_Policy: 'Dictionary_Validation'!$AL$3:$AL$5
Name List_Search_Optimization_Mode: 'Dictionary_Validation'!$AM$3:$AM$4
Name List_Search_Parameter_Scope: 'Dictionary_Validation'!$AN$3:$AN$5
Name List_Study_Type: 'Dictionary_Validation'!$AO$3:$AO$6
Name List_Study_Intent: 'Dictionary_Validation'!$AP$3:$AP$4
Name List_Factor_Type: 'Dictionary_Validation'!$AQ$3:$AQ$6
Name List_Replication_Mode: 'Dictionary_Validation'!$AR$3:$AR$5
Name List_Replication_Strategy: 'Dictionary_Validation'!$AS$3:$AS$6
Name List_Blocking_Strategy: 'Dictionary_Validation'!$AT$3:$AT$7
Name List_Randomization_Strategy: 'Dictionary_Validation'!$AU$3:$AU$7
Name List_Random_Seed_Policy: 'Dictionary_Validation'!$AV$3:$AV$5
Name List_Block_Type: 'Dictionary_Validation'!$AW$3:$AW$7
Name List_Design_Cell_Status: 'Dictionary_Validation'!$AX$3:$AX$7
Name List_Aggregation_Level: 'Dictionary_Validation'!$AY$3:$AY$7
Name List_Uncertainty_Method: 'Dictionary_Validation'!$AZ$3:$AZ$7
Name List_Multiplicity_Handling: 'Dictionary_Validation'!$BA$3:$BA$8
Name List_Interaction_Reporting_Policy: 'Dictionary_Validation'!$BB$3:$BB$6
Name List_Study_Review_Disposition: 'Dictionary_Validation'!$BC$3:$BC$5

Sheet README
A1: Thesis Experiment Program Workbook (v2.1)
A3: Purpose | B3: Single governance workbook for the thesis experiment program: design locking, data-slice control, grouping/split governance, robustness planning, confirmatory readiness, and thesis chapter mapping.
A5: How to use this workbook | B5: Follow the workflow in order: define experiments -> define data slices and grouping strategies -> lock decisions -> mark confirmatory package -> map claims and thesis sections -> monitor readiness on the dashboard.
A7: Human-managed sheets
A9: Machine-managed sheets | B9: Generated_Design_Matrix; Effect_Summaries; Artifact_Registry; Run_Log; Trial_Results; Summary_Outputs. These should be written by scripts or carefully imported, not manually edited during analysis runs.
A11: Core scientific framing | B11: Primary claim = within-person held-out-session generalization. Secondary claim = frozen directional cross-person transfer. Robustness analyses support interpretation but do not replace the primary confirmatory claim.
A13: Current modification scope
A15: Freeze policy | B15: Confirmatory eligibility requires the main decision locks (D01-D07) plus a documented supporting robustness package. Supporting robustness analyses may be pre-specified and confirmatory-eligible without all being required for the main claim.
A17: Interpretation rules | B17: Weak-split analyses are inflation demonstrations only. Cross-person results are not population-level claims. Interpretability outputs are model-behavior evidence, not direct neural localization evidence.
A19: Workflow
A21: Grouping_Strategy_Map | B21: Defines split family, train/test grouping units, leakage safeguards, and interpretation boundaries for each grouping strategy identifier.
A24: Data_Profile | B24: Structured worksheet for manual or imported descriptive counts by subject/session/task/modality/target/class and by Data_Slice_ID, with formula-based sparsity/imbalance flags.
A27: Claim boundaries | B27: Within-person held-out-session claims and cross-person transfer claims are different scientific claims and must not be interpreted interchangeably.
A30: Weak-split policy | B30: Weak split results are allowed only as inflation demonstrations and diagnostic contrast. They are not confirmatory evidence.
A33: Governance additions | B33: Claim_Ledger enforces claim discipline. AI_Usage_Log supports tool transparency and human verification traceability. Ethics_Governance_Notes supports risk/mitigation accountability.
A36: Workflow | B36: Master_Experiments + Data_Selection_Design + Grouping_Strategy_Map -> Run_Log -> Decision_Log -> Confirmatory_Set -> Claim_Ledger/AI_Usage_Log/Ethics_Governance_Notes -> Thesis_Map -> Dashboard.
A39: This workbook is aligned to thesis method-choice/method-application workflow, data-slice/grouping governance, and leakage-aware reporting requirements.
A41: Schema_Metadata_Key | B41: Value
A42: workbook_schema_version | B42: workbook-v1.1-robustness-plan
A43: compiled_manifest_schema_version | B43: compiled-manifest-v1
A44: artifact_schema_version | B44: artifact-v1
A45: workbook_writeback_schema_version | B45: workbook-writeback-v1
A46: summary_result_schema_version | B46: summary-result-v1
A47: thesis_protocol_schema_version | B47: thesis-protocol-v1
A48: artifact_schema_version | B48: artifact-v1
A49: workbook_writeback_schema_version | B49: workbook-writeback-v1
A50: summary_result_schema_version | B50: summary-result-v1
A51: thesis_protocol_schema_version | B51: thesis-protocol-v1
A52: Generated by create_thesis_experiment_workbook.py (v2)

Sheet Master_Experiments
A1: Experiment_ID | B1: Short_Title | C1: Category | D1: Evidential_Role | E1: Stage | F1: Priority | G1: Decision_Supported | H1: Exact_Question | I1: Hypothesis_or_Expectation | J1: Manipulated_Factor | K1: Held_Constant_Controls | L1: Dataset_Scope | M1: Target_Definition | N1: Split_Logic | O1: Leakage_Risk | P1: Leakage_Control | Q1: Models_Compared | R1: Primary_Metric | S1: Secondary_Metrics | T1: Robustness_Checks | U1: Decision_Criterion | V1: Success_Pattern | W1: Failure_or_Warning_Pattern | X1: Threats_to_Validity | Y1: Reporting_Destination | Z1: Interpretation_Boundary | AA1: Status | AB1: Owner | AC1: Outcome_Summary | AD1: Decision_Taken | AE1: Notes | AF1: Experiment_Ready
A2: E01 | B2: Target granularity experiment | C2: Target-definition | D2: Secondary decision-support | E2: Stage 1 - Target lock | F2: High | G2: Final target lock | H2: Should the thesis use fine-grained emotion labels, three-class coarse affect, or binary valence-like labels? | I2: coarse_affect likely balances construct validity, class balance, and learnability. | J2: Target definition | K2: Dataset index version, train-only fitting policy, metric definitions, seed policy, artifact schema. | L2: Internal repeated-session BAS2 dataset (sub-001 and sub-002) unless explicitly external. | M2: fine emotion vs coarse_affect vs binary valence-like | N2: within_subject_loso_session under matched target-comparison controls | O2: Performance inflation if split logic or fit scope leaks train/test information. | P2: Predefined split manifests and train-only fitting; no test-driven tuning or target redesign. | Q2: ridge baseline unless model family is manipulated. | R2: Balanced accuracy | S2: Macro-F1; class-wise recall; accuracy | T2: Fold-level checks and stress controls where relevant. | U2: Prefer target balancing construct validity, class balance, sample sufficiency, and learnability under claim-matched evaluation. | V2: Stable claim-consistent performance without leakage indicators. | W2: Weak-split inflation, instability, class collapse, or directionally inconsistent evidence. | X2: Class imbalance, sample limits, domain shift, and model/split sensitivity. | Y2: Chapter 3 Method choice | Z2: Interpret only under stated split logic/evidence tier; no causal or localization claims. | AA2: Planned | AB2: Khaled (thesis author) | AF2: =IF($AA2="Dropped","N/A",IF(AND($H2<>"",$J2<>"",$K2<>"",$M2<>"",$N2<>"",$P2<>"",$R2<>"",$U2<>"",$V2<>"",$W2<>"",$Z2<>"",$Y2<>""),"READY","INCOMPLETE"))
A3: E02 | B3: Task pooling experiment | C3: Target-definition | D3: Secondary decision-support | E3: Stage 1 - Target lock | F3: Medium | G3: Task pooling policy | H3: Should the main target be learned across all tasks together, or separately by task? | I3: Evaluate under leakage-aware claim-matched split logic before interpretation. | J3: Pooling strategy by task | K3: Dataset index version, train-only fitting policy, metric definitions, seed policy, artifact schema. | L3: Internal repeated-session BAS2 dataset (sub-001 and sub-002) unless explicitly external. | M3: coarse_affect unless this experiment manipulates target granularity. | N3: Claim-matched leakage-safe split strategy. | O3: Performance inflation if split logic or fit scope leaks train/test information. | P3: Predefined split manifests, train-only fitting, frozen transfer where applicable, no test-driven tuning. | Q3: ridge baseline unless model family is manipulated. | R3: Balanced accuracy | S3: Macro-F1; class-wise recall; accuracy | T3: Fold-level checks and stress controls where relevant. | U3: Pre-specified criterion recorded before interpretation. | V3: Stable claim-consistent performance without leakage indicators. | W3: Weak-split inflation, instability, class collapse, or directionally inconsistent evidence. | X3: Class imbalance, sample limits, domain shift, and model/split sensitivity. | Y3: Chapter 3 Method choice | Z3: Interpret only under stated split logic/evidence tier; no causal or localization claims. | AA3: Planned | AB3: Khaled (thesis author) | AF3: =IF($AA3="Dropped","N/A",IF(AND($H3<>"",$J3<>"",$K3<>"",$M3<>"",$N3<>"",$P3<>"",$R3<>"",$U3<>"",$V3<>"",$W3<>"",$Z3<>"",$Y3<>""),"READY","INCOMPLETE"))
A4: E03 | B4: Modality pooling experiment | C4: Target-definition | D4: Secondary decision-support | E4: Stage 1 - Target lock | F4: Medium | G4: Modality pooling policy | H4: Should audio, video, and audiovisual conditions be pooled or modeled separately? | I4: Evaluate under leakage-aware claim-matched split logic before interpretation. | J4: Pooling strategy by modality | K4: Dataset index version, train-only fitting policy, metric definitions, seed policy, artifact schema. | L4: Internal repeated-session BAS2 dataset (sub-001 and sub-002) unless explicitly external. | M4: coarse_affect unless this experiment manipulates target granularity. | N4: Claim-matched leakage-safe split strategy. | O4: Performance inflation if split logic or fit scope leaks train/test information. | P4: Predefined split manifests, train-only fitting, frozen transfer where applicable, no test-driven tuning. | Q4: ridge baseline unless model family is manipulated. | R4: Balanced accuracy | S4: Macro-F1; class-wise recall; accuracy | T4: Fold-level checks and stress controls where relevant. | U4: Pre-specified criterion recorded before interpretation. | V4: Stable claim-consistent performance without leakage indicators. | W4: Weak-split inflation, instability, class collapse, or directionally inconsistent evidence. | X4: Class imbalance, sample limits, domain shift, and model/split sensitivity. | Y4: Chapter 3 Method choice | Z4: Interpret only under stated split logic/evidence tier; no causal or localization claims. | AA4: Planned | AB4: Khaled (thesis author) | AF4: =IF($AA4="Dropped","N/A",IF(AND($H4<>"",$J4<>"",$K4<>"",$M4<>"",$N4<>"",$P4<>"",$R4<>"",$U4<>"",$V4<>"",$W4<>"",$Z4<>"",$Y4<>""),"READY","INCOMPLETE"))
A5: E04 | B5: Split-strength stress test | C5: Split-design | D5: Secondary decision-support | E5: Stage 2 - Split lock | F5: High | G5: Primary split policy | H5: How much do conclusions change under weaker split strategies compared with session-held-out evaluation? | I5: Evaluate under leakage-aware claim-matched split logic before interpretation. | J5: Split logic | K5: Dataset index version, train-only fitting policy, metric definitions, seed policy, artifact schema. | L5: Internal repeated-session BAS2 dataset (sub-001 and sub-002) unless explicitly external. | M5: coarse_affect unless this experiment manipulates target granularity. | N5: record-wise random split vs weaker grouped split vs within-person leave-one-session-out | O5: High under weak splits | P5: Predefined split manifests, train-only fitting, frozen transfer where applicable, no test-driven tuning. | Q5: ridge baseline unless model family is manipulated. | R5: Balanced accuracy | S5: Macro-F1; class-wise recall; accuracy | T5: Fold-level checks and stress controls where relevant. | U5: Retain strictest split matching claim; weaker splits only as inflation/leakage demonstrations. | V5: Stable claim-consistent performance without leakage indicators. | W5: Weak-split inflation, instability, class collapse, or directionally inconsistent evidence. | X5: Class imbalance, sample limits, domain shift, and model/split sensitivity. | Y5: Chapter 3 Method choice | Z5: Interpret only under stated split logic/evidence tier; no causal or localization claims. | AA5: Planned | AB5: Khaled (thesis author) | AF5: =IF($AA5="Dropped","N/A",IF(AND($H5<>"",$J5<>"",$K5<>"",$M5<>"",$N5<>"",$P5<>"",$R5<>"",$U5<>"",$V5<>"",$W5<>"",$Z5<>"",$Y5<>""),"READY","INCOMPLETE"))
A6: E05 | B6: Cross-person transfer design | C6: Split-design | D6: Secondary decision-support | E6: Stage 2 - Split lock | F6: High | G6: Cross-person transfer framing | H6: How should cross-person generalization be framed and evaluated? | I6: Evaluate under leakage-aware claim-matched split logic before interpretation. | J6: Transfer protocol | K6: Dataset index version, train-only fitting policy, metric definitions, seed policy, artifact schema. | L6: Internal repeated-session BAS2 dataset (sub-001 and sub-002) unless explicitly external. | M6: coarse_affect unless this experiment manipulates target granularity. | N6: frozen train-on-A/test-on-B and reverse direction | O6: Performance inflation if split logic or fit scope leaks train/test information. | P6: Fit only on train subject; no test subject re-fit/re-tune | Q6: ridge baseline unless model family is manipulated. | R6: Balanced accuracy | S6: Macro-F1; class-wise recall; accuracy | T6: Fold-level checks and stress controls where relevant. | U6: Keep frozen directional transfer as clean cross-case test. | V6: Stable claim-consistent performance without leakage indicators. | W6: Weak-split inflation, instability, class collapse, or directionally inconsistent evidence. | X6: Class imbalance, sample limits, domain shift, and model/split sensitivity. | Y6: Chapter 3 Method choice | Z6: Transfer evidence under domain shift, not population-level generalization. | AA6: Planned | AB6: Khaled (thesis author) | AF6: =IF($AA6="Dropped","N/A",IF(AND($H6<>"",$J6<>"",$K6<>"",$M6<>"",$N6<>"",$P6<>"",$R6<>"",$U6<>"",$V6<>"",$W6<>"",$Z6<>"",$Y6<>""),"READY","INCOMPLETE"))
A7: E06 | B7: Linear model family comparison | C7: Model-comparison | D7: Secondary decision-support | E7: Stage 3 - Model lock | F7: High | G7: Model family lock | H7: Which linear model is the most appropriate default: ridge, logistic regression, or linear SVM? | I7: Evaluate under leakage-aware claim-matched split logic before interpretation. | J7: Model family | K7: Dataset index version, train-only fitting policy, metric definitions, seed policy, artifact schema. | L7: Internal repeated-session BAS2 dataset (sub-001 and sub-002) unless explicitly external. | M7: coarse_affect unless this experiment manipulates target granularity. | N7: Claim-matched leakage-safe split strategy. | O7: Performance inflation if split logic or fit scope leaks train/test information. | P7: Predefined split manifests, train-only fitting, frozen transfer where applicable, no test-driven tuning. | Q7: ridge vs logreg vs linearsvc | R7: Balanced accuracy | S7: Macro-F1; class-wise recall; accuracy | T7: Fold-level checks and stress controls where relevant. | U7: Prefer simplest model with comparable predictive performance and better robustness/stability. | V7: Stable claim-consistent performance without leakage indicators. | W7: Weak-split inflation, instability, class collapse, or directionally inconsistent evidence. | X7: Class imbalance, sample limits, domain shift, and model/split sensitivity. | Y7: Chapter 3 Method choice | Z7: Interpret only under stated split logic/evidence tier; no causal or localization claims. | AA7: Planned | AB7: Khaled (thesis author) | AF7: =IF($AA7="Dropped","N/A",IF(AND($H7<>"",$J7<>"",$K7<>"",$M7<>"",$N7<>"",$P7<>"",$R7<>"",$U7<>"",$V7<>"",$W7<>"",$Z7<>"",$Y7<>""),"READY","INCOMPLETE"))
A8: E07 | B8: Class weighting experiment | C8: Model-comparison | D8: Secondary decision-support | E8: Stage 3 - Model lock | F8: Medium | G8: Weighting policy | H8: Does class weighting improve fairness across classes without creating instability? | I8: Evaluate under leakage-aware claim-matched split logic before interpretation. | J8: Weighting strategy | K8: Dataset index version, train-only fitting policy, metric definitions, seed policy, artifact schema. | L8: Internal repeated-session BAS2 dataset (sub-001 and sub-002) unless explicitly external. | M8: coarse_affect unless this experiment manipulates target granularity. | N8: Claim-matched leakage-safe split strategy. | O8: Performance inflation if split logic or fit scope leaks train/test information. | P8: Predefined split manifests, train-only fitting, frozen transfer where applicable, no test-driven tuning. | Q8: ridge baseline unless model family is manipulated. | R8: Balanced accuracy | S8: Macro-F1; class-wise recall; accuracy | T8: Fold-level checks and stress controls where relevant. | U8: Pre-specified criterion recorded before interpretation. | V8: Stable claim-consistent performance without leakage indicators. | W8: Weak-split inflation, instability, class collapse, or directionally inconsistent evidence. | X8: Class imbalance, sample limits, domain shift, and model/split sensitivity. | Y8: Chapter 3 Method choice | Z8: Interpret only under stated split logic/evidence tier; no causal or localization claims. | AA8: Planned | AB8: Khaled (thesis author) | AF8: =IF($AA8="Dropped","N/A",IF(AND($H8<>"",$J8<>"",$K8<>"",$M8<>"",$N8<>"",$P8<>"",$R8<>"",$U8<>"",$V8<>"",$W8<>"",$Z8<>"",$Y8<>""),"READY","INCOMPLETE"))
A9: E08 | B9: Hyperparameter strategy experiment | C9: Model-comparison | D9: Secondary decision-support | E9: Stage 3 - Model lock | F9: Medium | G9: Tuning policy | H9: Are fixed conservative hyperparameters sufficient, or does light nested tuning materially improve results? | I9: Evaluate under leakage-aware claim-matched split logic before interpretation. | J9: Tuning strategy | K9: Dataset index version, train-only fitting policy, metric definitions, seed policy, artifact schema. | L9: Internal repeated-session BAS2 dataset (sub-001 and sub-002) unless explicitly external. | M9: coarse_affect unless this experiment manipulates target granularity. | N9: Claim-matched leakage-safe split strategy. | O9: Performance inflation if split logic or fit scope leaks train/test information. | P9: Predefined split manifests, train-only fitting, frozen transfer where applicable, no test-driven tuning. | Q9: ridge baseline unless model family is manipulated. | R9: Balanced accuracy | S9: Macro-F1; class-wise recall; accuracy | T9: Fold-level checks and stress controls where relevant. | U9: Keep fixed settings unless nested tuning yields a clear and stable gain. | V9: Stable claim-consistent performance without leakage indicators. | W9: Weak-split inflation, instability, class collapse, or directionally inconsistent evidence. | X9: Class imbalance, sample limits, domain shift, and model/split sensitivity. | Y9: Chapter 3 Method choice | Z9: Interpret only under stated split logic/evidence tier; no causal or localization claims. | AA9: Planned | AB9: Khaled (thesis author) | AF9: =IF($AA9="Dropped","N/A",IF(AND($H9<>"",$J9<>"",$K9<>"",$M9<>"",$N9<>"",$P9<>"",$R9<>"",$U9<>"",$V9<>"",$W9<>"",$Z9<>"",$Y9<>""),"READY","INCOMPLETE"))
A10: E09 | B10: Whole-brain versus ROI experiment | C10: Preprocessing-feature | D10: Secondary decision-support | E10: Stage 4 - Feature/preprocessing lock | F10: Medium | G10: Feature representation lock | H10: Should the primary representation remain whole-brain masked voxels or use theory-justified ROIs? | I10: Evaluate under leakage-aware claim-matched split logic before interpretation. | J10: Feature space | K10: Dataset index version, train-only fitting policy, metric definitions, seed policy, artifact schema. | L10: Internal repeated-session BAS2 dataset (sub-001 and sub-002) unless explicitly external. | M10: coarse_affect unless this experiment manipulates target granularity. | N10: Claim-matched leakage-safe split strategy. | O10: Performance inflation if split logic or fit scope leaks train/test information. | P10: Predefined split manifests, train-only fitting, frozen transfer where applicable, no test-driven tuning. | Q10: ridge baseline unless model family is manipulated. | R10: Balanced accuracy | S10: Macro-F1; class-wise recall; accuracy | T10: Fold-level checks and stress controls where relevant. | U10: Pre-specified criterion recorded before interpretation. | V10: Stable claim-consistent performance without leakage indicators. | W10: Weak-split inflation, instability, class collapse, or directionally inconsistent evidence. | X10: Class imbalance, sample limits, domain shift, and model/split sensitivity. | Y10: Chapter 3 Method choice | Z10: Interpret only under stated split logic/evidence tier; no causal or localization claims. | AA10: Planned | AB10: Khaled (thesis author) | AF10: =IF($AA10="Dropped","N/A",IF(AND($H10<>"",$J10<>"",$K10<>"",$M10<>"",$N10<>"",$P10<>"",$R10<>"",$U10<>"",$V10<>"",$W10<>"",$Z10<>"",$Y10<>""),"READY","INCOMPLETE"))
A11: E10 | B11: Dimensionality reduction experiment | C11: Preprocessing-feature | D11: Secondary decision-support | E11: Stage 4 - Feature/preprocessing lock | F11: Medium | G11: Feature reduction policy | H11: Does unsupervised dimensionality reduction improve performance or stability enough to justify added complexity? | I11: Evaluate under leakage-aware claim-matched split logic before interpretation. | J11: Feature reduction strategy | K11: Dataset index version, train-only fitting policy, metric definitions, seed policy, artifact schema. | L11: Internal repeated-session BAS2 dataset (sub-001 and sub-002) unless explicitly external. | M11: coarse_affect unless this experiment manipulates target granularity. | N11: Claim-matched leakage-safe split strategy. | O11: Performance inflation if split logic or fit scope leaks train/test information. | P11: Predefined split manifests, train-only fitting, frozen transfer where applicable, no test-driven tuning. | Q11: ridge baseline unless model family is manipulated. | R11: Balanced accuracy | S11: Macro-F1; class-wise recall; accuracy | T11: Fold-level checks and stress controls where relevant. | U11: Pre-specified criterion recorded before interpretation. | V11: Stable claim-consistent performance without leakage indicators. | W11: Weak-split inflation, instability, class collapse, or directionally inconsistent evidence. | X11: Class imbalance, sample limits, domain shift, and model/split sensitivity. | Y11: Chapter 3 Method choice | Z11: Interpret only under stated split logic/evidence tier; no causal or localization claims. | AA11: Planned | AB11: Khaled (thesis author) | AF11: =IF($AA11="Dropped","N/A",IF(AND($H11<>"",$J11<>"",$K11<>"",$M11<>"",$N11<>"",$P11<>"",$R11<>"",$U11<>"",$V11<>"",$W11<>"",$Z11<>"",$Y11<>""),"READY","INCOMPLETE"))
A12: E11 | B12: Scaling and normalization experiment | C12: Preprocessing-feature | D12: Secondary decision-support | E12: Stage 4 - Feature/preprocessing lock | F12: Medium | G12: Scaling policy lock | H12: How sensitive are the results to scaling strategy? | I12: Evaluate under leakage-aware claim-matched split logic before interpretation. | J12: Scaling policy | K12: Dataset index version, train-only fitting policy, metric definitions, seed policy, artifact schema. | L12: Internal repeated-session BAS2 dataset (sub-001 and sub-002) unless explicitly external. | M12: coarse_affect unless this experiment manipulates target granularity. | N12: Claim-matched leakage-safe split strategy. | O12: Performance inflation if split logic or fit scope leaks train/test information. | P12: Predefined split manifests, train-only fitting, frozen transfer where applicable, no test-driven tuning. | Q12: ridge baseline unless model family is manipulated. | R12: Balanced accuracy | S12: Macro-F1; class-wise recall; accuracy | T12: Fold-level checks and stress controls where relevant. | U12: Pre-specified criterion recorded before interpretation. | V12: Stable claim-consistent performance without leakage indicators. | W12: Weak-split inflation, instability, class collapse, or directionally inconsistent evidence. | X12: Class imbalance, sample limits, domain shift, and model/split sensitivity. | Y12: Chapter 3 Method choice | Z12: Interpret only under stated split logic/evidence tier; no causal or localization claims. | AA12: Planned | AB12: Khaled (thesis author) | AF12: =IF($AA12="Dropped","N/A",IF(AND($H12<>"",$J12<>"",$K12<>"",$M12<>"",$N12<>"",$P12<>"",$R12<>"",$U12<>"",$V12<>"",$W12<>"",$Z12<>"",$Y12<>""),"READY","INCOMPLETE"))
A13: E12 | B13: Permutation test experiment | C13: Robustness | D13: Primary-supporting robustness | E13: Stage 6 - Robustness analysis | F13: High | G13: Chance-level distinguishability support | H13: Are the main predictive results distinguishable from chance under the exact same split logic? | I13: Evaluate under leakage-aware claim-matched split logic before interpretation. | J13: Label structure (true vs permuted) | K13: Dataset index version, train-only fitting policy, metric definitions, seed policy, artifact schema. | L13: Internal repeated-session BAS2 dataset (sub-001 and sub-002) unless explicitly external. | M13: coarse_affect unless this experiment manipulates target granularity. | N13: exact confirmatory split logic with train-only permutation | O13: Performance inflation if split logic or fit scope leaks train/test information. | P13: Predefined split manifests, train-only fitting, frozen transfer where applicable, no test-driven tuning. | Q13: ridge baseline unless model family is manipulated. | R13: Balanced accuracy | S13: Empirical p-value; null distribution summary | T13: Fold-level checks and stress controls where relevant. | U13: Pre-specified criterion recorded before interpretation. | V13: Stable claim-consistent performance without leakage indicators. | W13: Weak-split inflation, instability, class collapse, or directionally inconsistent evidence. | X13: Class imbalance, sample limits, domain shift, and model/split sensitivity. | Y13: Chapter 4 Supporting robustness | Z13: Interpret only under stated split logic/evidence tier; no causal or localization claims. | AA13: Planned | AB13: Khaled (thesis author) | AF13: =IF($AA13="Dropped","N/A",IF(AND($H13<>"",$J13<>"",$K13<>"",$M13<>"",$N13<>"",$P13<>"",$R13<>"",$U13<>"",$V13<>"",$W13<>"",$Z13<>"",$Y13<>""),"READY","INCOMPLETE"))
A14: E13 | B14: Trivial baseline experiment | C14: Robustness | D14: Primary-supporting robustness | E14: Stage 6 - Robustness analysis | F14: High | G14: Non-trivial predictive value support | H14: Does the final model clearly outperform trivial baselines? | I14: Evaluate under leakage-aware claim-matched split logic before interpretation. | J14: Baseline type | K14: Dataset index version, train-only fitting policy, metric definitions, seed policy, artifact schema. | L14: Internal repeated-session BAS2 dataset (sub-001 and sub-002) unless explicitly external. | M14: coarse_affect unless this experiment manipulates target granularity. | N14: Claim-matched leakage-safe split strategy. | O14: Performance inflation if split logic or fit scope leaks train/test information. | P14: Predefined split manifests, train-only fitting, frozen transfer where applicable, no test-driven tuning. | Q14: Final locked model vs trivial baselines | R14: Balanced accuracy | S14: Macro-F1; class-wise recall; accuracy | T14: Fold-level checks and stress controls where relevant. | U14: Pre-specified criterion recorded before interpretation. | V14: Stable claim-consistent performance without leakage indicators. | W14: Weak-split inflation, instability, class collapse, or directionally inconsistent evidence. | X14: Class imbalance, sample limits, domain shift, and model/split sensitivity. | Y14: Chapter 4 Supporting robustness | Z14: Interpret only under stated split logic/evidence tier; no causal or localization claims. | AA14: Planned | AB14: Khaled (thesis author) | AF14: =IF($AA14="Dropped","N/A",IF(AND($H14<>"",$J14<>"",$K14<>"",$M14<>"",$N14<>"",$P14<>"",$R14<>"",$U14<>"",$V14<>"",$W14<>"",$Z14<>"",$Y14<>""),"READY","INCOMPLETE"))
A15: E14 | B15: Quantified explanation stability | C15: Robustness | D15: Primary-supporting robustness | E15: Stage 6 - Robustness analysis | F15: High | G15: Interpretability stability support | H15: Are linear coefficient or importance patterns stable across held-out-session folds and reruns of the same locked pipeline? | I15: Explanation patterns should show at least directional consistency if they are to support interpretation. | J15: Explanation stability metric | K15: Dataset index version, train-only fitting policy, metric definitions, seed policy, artifact schema. | L15: Internal repeated-session BAS2 dataset (sub-001 and sub-002) unless explicitly external. | M15: coarse_affect unless this experiment manipulates target granularity. | N15: Claim-matched leakage-safe split strategy with fold-wise explanation extraction. | O15: Performance inflation if split logic or fit scope leaks train/test information. | P15: Predefined split manifests, train-only fitting, frozen transfer where applicable, no test-driven tuning. | Q15: ridge baseline unless model family is manipulated. | R15: Mean pairwise coefficient correlation | S15: Sign consistency; top-k overlap; spatial agreement | T15: Fold-wise and rerun stability summaries linked to the same confirmatory base run. | U15: Use interpretation support only if explanation patterns are not dominated by fold-specific instability. | V15: Stable fold-level explanation patterns without contradiction across the main held-out-session analyses. | W15: Highly unstable maps, sign flips, or dependence on a tiny subset of folds. | X15: Model instability, small-sample variability, and over-interpretation of feature weights. | Y15: Chapter 4 Supporting robustness | Z15: Model-behavior evidence only; not direct neural localization. | AA15: Planned | AB15: Khaled (thesis author) | AE15: Replaces vague explanation language with explicit stability metrics.
A16: E15 | B16: Subset sensitivity framing | C16: Robustness | D16: Secondary decision-support / robustness | E16: Stage 6 - Robustness analysis | F16: Medium | G16: Sensitivity framing | H16: Do the main conclusions depend excessively on one subset, such as one task, one modality, or one session cluster? | I16: The main conclusion should not collapse when a single plausible subset is excluded. | J16: Subset inclusion / exclusion policy | K16: Dataset index version, train-only fitting policy, metric definitions, seed policy, artifact schema. | L16: Internal repeated-session BAS2 dataset (sub-001 and sub-002) unless explicitly external. | M16: coarse_affect unless this experiment manipulates target granularity. | N16: Claim-matched leakage-safe split strategy plus pre-registered subset exclusions. | O16: Performance inflation if split logic or fit scope leaks train/test information. | P16: Predefined split manifests, train-only fitting, frozen transfer where applicable, no test-driven tuning. | Q16: ridge baseline unless model family is manipulated. | R16: Balanced accuracy | S16: Macro-F1; class-wise recall; accuracy | T16: Subset-specific reruns and omission diagnostics where relevant. | U16: Use as a framing experiment to decide whether stronger dedicated sensitivity checks are needed. | V16: Directionally similar conclusions across pre-registered subset variants. | W16: Large dependence on one subset or a reversal of the main conclusion. | X16: Class imbalance, sample limits, domain shift, and model/split sensitivity. | Y16: Chapter 5 Discussion | Z16: Interpret only under stated split logic/evidence tier; no causal or localization claims. | AA16: Planned | AB16: Khaled (thesis author) | AE16: Parent sensitivity entry complemented by E21-E23 for more specific robustness checks.
A17: E16 | B17: Final within-person confirmatory analysis | C17: Confirmatory core | D17: Primary confirmatory | E17: Stage 5 - Confirmatory analysis | F17: Critical | G17: Primary confirmatory claim | H17: Does the final locked pipeline show meaningful within-person held-out-session generalization? | I17: Evaluate under leakage-aware claim-matched split logic before interpretation. | J17: None; final frozen pipeline | K17: Dataset index version, train-only fitting policy, metric definitions, seed policy, artifact schema. | L17: Internal repeated-session BAS2 dataset (sub-001 and sub-002) unless explicitly external. | M17: Locked target after Stage 1 target lock | N17: within_subject_loso_session | O17: Performance inflation if split logic or fit scope leaks train/test information. | P17: Predefined split manifests, train-only fitting, frozen transfer where applicable, no test-driven tuning. | Q17: Final locked model | R17: Balanced accuracy | S17: Macro-F1; class-wise recall; accuracy | T17: Fold-level checks and stress controls where relevant. | U17: Primary evidential core of thesis. | V17: Stable claim-consistent performance without leakage indicators. | W17: Weak-split inflation, instability, class collapse, or directionally inconsistent evidence. | X17: Class imbalance, sample limits, domain shift, and model/split sensitivity. | Y17: Chapter 4 Main results | Z17: Interpret only under stated split logic/evidence tier; no causal or localization claims. | AA17: Planned | AB17: Khaled (thesis author) | AF17: =IF($AA17="Dropped","N/A",IF(AND($H17<>"",$J17<>"",$K17<>"",$M17<>"",$N17<>"",$P17<>"",$R17<>"",$U17<>"",$V17<>"",$W17<>"",$Z17<>"",$Y17<>""),"READY","INCOMPLETE"))
A18: E17 | B18: Final cross-person transfer analysis | C18: Confirmatory core | D18: Primary confirmatory | E18: Stage 5 - Confirmatory analysis | F18: Critical | G18: Secondary confirmatory transfer claim | H18: Does the final locked pipeline transfer meaningfully across individuals under frozen directional transfer? | I18: Evaluate under leakage-aware claim-matched split logic before interpretation. | J18: None; final frozen pipeline | K18: Dataset index version, train-only fitting policy, metric definitions, seed policy, artifact schema. | L18: Internal repeated-session BAS2 dataset (sub-001 and sub-002) unless explicitly external. | M18: Locked target after Stage 1 target lock | N18: frozen_cross_person_transfer both directions | O18: Performance inflation if split logic or fit scope leaks train/test information. | P18: Predefined split manifests, train-only fitting, frozen transfer where applicable, no test-driven tuning. | Q18: Final locked model | R18: Balanced accuracy | S18: Macro-F1; class-wise recall; accuracy | T18: Fold-level checks and stress controls where relevant. | U18: Interpret as cross-case transfer evidence under domain shift. | V18: Stable claim-consistent performance without leakage indicators. | W18: Weak-split inflation, instability, class collapse, or directionally inconsistent evidence. | X18: Class imbalance, sample limits, domain shift, and model/split sensitivity. | Y18: Chapter 4 Main results | Z18: Directional transfer evidence only; not population-level generalization. | AA18: Planned | AB18: Khaled (thesis author) | AF18: =IF($AA18="Dropped","N/A",IF(AND($H18<>"",$J18<>"",$K18<>"",$M18<>"",$N18<>"",$P18<>"",$R18<>"",$U18<>"",$V18<>"",$W18<>"",$Z18<>"",$Y18<>""),"READY","INCOMPLETE"))
A19: E18 | B19: External open-source split replication | C19: External exploratory | D19: Exploratory extension | E19: Stage 7 - Exploratory extension | F19: Low | G19: External split-consistency exploration | H19: Does the same leakage-aware split logic materially affect conclusions on a compatible external open-source dataset? | I19: Evaluate under leakage-aware claim-matched split logic before interpretation. | J19: Dataset source | K19: Dataset index version, train-only fitting policy, metric definitions, seed policy, artifact schema. | L19: External open-source dataset if available and approved | M19: coarse_affect unless this experiment manipulates target granularity. | N19: Claim-matched leakage-safe split strategy. | O19: Performance inflation if split logic or fit scope leaks train/test information. | P19: Predefined split manifests, train-only fitting, frozen transfer where applicable, no test-driven tuning. | Q19: ridge baseline unless model family is manipulated. | R19: Balanced accuracy | S19: Macro-F1; class-wise recall; accuracy | T19: Fold-level checks and stress controls where relevant. | U19: Pre-specified criterion recorded before interpretation. | V19: Stable claim-consistent performance without leakage indicators. | W19: Weak-split inflation, instability, class collapse, or directionally inconsistent evidence. | X19: Class imbalance, sample limits, domain shift, and model/split sensitivity. | Y19: Appendix | Z19: Interpret only under stated split logic/evidence tier; no causal or localization claims. | AA19: Planned | AB19: Khaled (thesis author) | AF19: =IF($AA19="Dropped","N/A",IF(AND($H19<>"",$J19<>"",$K19<>"",$M19<>"",$N19<>"",$P19<>"",$R19<>"",$U19<>"",$V19<>"",$W19<>"",$Z19<>"",$Y19<>""),"READY","INCOMPLETE"))
A20: E19 | B20: External open-source model portability | C20: External exploratory | D20: Exploratory extension | E20: Stage 7 - Exploratory extension | F20: Low | G20: External model portability exploration | H20: Does the relative ranking of reasonable model choices remain similar on external data? | I20: Evaluate under leakage-aware claim-matched split logic before interpretation. | J20: Dataset source with same small model set | K20: Dataset index version, train-only fitting policy, metric definitions, seed policy, artifact schema. | L20: External open-source dataset if available and approved | M20: coarse_affect unless this experiment manipulates target granularity. | N20: Claim-matched leakage-safe split strategy. | O20: Performance inflation if split logic or fit scope leaks train/test information. | P20: Predefined split manifests, train-only fitting, frozen transfer where applicable, no test-driven tuning. | Q20: ridge vs logreg vs linearsvc | R20: Balanced accuracy | S20: Macro-F1; class-wise recall; accuracy | T20: Fold-level checks and stress controls where relevant. | U20: Pre-specified criterion recorded before interpretation. | V20: Stable claim-consistent performance without leakage indicators. | W20: Weak-split inflation, instability, class collapse, or directionally inconsistent evidence. | X20: Class imbalance, sample limits, domain shift, and model/split sensitivity. | Y20: Appendix | Z20: Interpret only under stated split logic/evidence tier; no causal or localization claims. | AA20: Planned | AB20: Khaled (thesis author) | AF20: =IF($AA20="Dropped","N/A",IF(AND($H20<>"",$J20<>"",$K20<>"",$M20<>"",$N20<>"",$P20<>"",$R20<>"",$U20<>"",$V20<>"",$W20<>"",$Z20<>"",$Y20<>""),"READY","INCOMPLETE"))
A21: E20 | B21: Confound diagnostics package | C21: Robustness | D21: Primary-supporting robustness | E21: Stage 6 - Robustness analysis | F21: High | G21: Confound-risk interpretation support | H21: Can the same feature space decode non-target variables such as task, modality, or session proxy strongly enough to challenge the preferred interpretation? | I21: Main affect-decoding evidence should not be explained away by obviously stronger non-target structure. | J21: Diagnostic target and nuisance structure | K21: Dataset index version, train-only fitting policy, metric definitions, seed policy, artifact schema. | L21: Internal repeated-session BAS2 dataset (sub-001 and sub-002) unless explicitly external. | M21: coarse_affect plus non-target diagnostic labels | N21: within_subject_loso_session under matched diagnostic setups | O21: Risk that non-target structure masquerades as target signal. | P21: Train-only fitting, matched diagnostic pipeline, no test-driven target redesign. | Q21: ridge baseline unless model family is manipulated. | R21: Balanced accuracy | S21: Macro-F1; diagnostic class recall | T21: Compare target decoding with task/modality/session-proxy diagnostic decoding. | U21: Use to narrow interpretation if non-target structure appears dominant or easier to decode than the target. | V21: Target result remains interpretable after diagnostic comparison and nuisance review. | W21: Non-target diagnostics dominate or strongly compete with the target explanation. | X21: Confounding structure, task dependence, modality effects, session drift. | Y21: Chapter 4 Supporting robustness | Z21: Interpretation-boundary evidence only; can narrow claims even when the main result remains positive. | AA21: Planned | AB21: Khaled (thesis author) | AE21: New high-value validity experiment.
A22: E21 | B22: Leave-task-out generalization | C22: Robustness | D22: Primary-supporting robustness | E22: Stage 6 - Robustness analysis | F22: High | G22: Task-generalization support | H22: Does a model trained without one task retain directionally similar performance when evaluated on the held-out task within subject? | I22: If the signal is partly task-general, held-out-task performance should remain directionally supportive. | J22: Held-out task | K22: Dataset index version, train-only fitting policy, metric definitions, seed policy, artifact schema. | L22: Internal repeated-session BAS2 dataset (sub-001 and sub-002) unless explicitly external. | M22: coarse_affect unless this experiment manipulates target granularity. | N22: leave-task-out within subject | O22: Performance inflation if split logic or fit scope leaks train/test information. | P22: Held-out task excluded from all train-side fitting and tuning steps. | Q22: ridge baseline unless model family is manipulated. | R22: Balanced accuracy | S22: Macro-F1; class-wise recall; accuracy | T22: Held-out task comparisons against the locked pooled-task baseline. | U22: Use as supporting robustness, not as a replacement for the primary held-out-session claim. | V22: Directionally supportive performance on held-out tasks without collapse. | W22: Performance collapses on held-out tasks, suggesting strong task-bound signal. | X22: Task-specific confounding, sample imbalance, limited task coverage. | Y22: Chapter 4 Supporting robustness | Z22: Task-generalization support only; not the primary confirmatory split. | AA22: Planned | AB22: Khaled (thesis author) | AE22: New robustness experiment focused on construct validity across tasks.
A23: E22 | B23: Leave-modality-out generalization | C23: Robustness | D23: Primary-supporting robustness | E23: Stage 6 - Robustness analysis | F23: High | G23: Modality-generalization support | H23: Does a model trained without one modality retain directionally similar performance when evaluated on the held-out modality within subject? | I23: If the signal is partly modality-general, held-out-modality performance should remain directionally supportive. | J23: Held-out modality | K23: Dataset index version, train-only fitting policy, metric definitions, seed policy, artifact schema. | L23: Internal repeated-session BAS2 dataset (sub-001 and sub-002) unless explicitly external. | M23: coarse_affect unless this experiment manipulates target granularity. | N23: leave-modality-out within subject | O23: Performance inflation if split logic or fit scope leaks train/test information. | P23: Held-out modality excluded from all train-side fitting and tuning steps. | Q23: ridge baseline unless model family is manipulated. | R23: Balanced accuracy | S23: Macro-F1; class-wise recall; accuracy | T23: Held-out modality comparisons against the locked pooled-modality baseline. | U23: Use as supporting robustness, not as a replacement for the primary held-out-session claim. | V23: Directionally supportive performance on held-out modalities without collapse. | W23: Performance collapses on held-out modalities, suggesting strong modality-bound signal. | X23: Modality-specific confounding, sample imbalance, limited modality coverage. | Y23: Chapter 4 Supporting robustness | Z23: Modality-generalization support only; not the primary confirmatory split. | AA23: Planned | AB23: Khaled (thesis author) | AE23: New robustness experiment focused on construct validity across modalities.
A24: E23 | B24: Session-influence / jackknife robustness | C24: Robustness | D24: Primary-supporting robustness | E24: Stage 6 - Robustness analysis | F24: High | G24: Session-influence robustness support | H24: Do the main conclusions remain directionally stable when one designated session or subset is omitted from the training pool? | I24: A stable result should not depend entirely on one unusually easy or unusually clean session. | J24: Omitted session or subset | K24: Dataset index version, train-only fitting policy, metric definitions, seed policy, artifact schema. | L24: Internal repeated-session BAS2 dataset (sub-001 and sub-002) unless explicitly external. | M24: coarse_affect unless this experiment manipulates target granularity. | N24: session-influence exclusion under the same held-out-session framework | O24: Performance inflation if split logic or fit scope leaks train/test information. | P24: One omission at a time; omitted subset excluded from all train-side transforms and summaries. | Q24: ridge baseline unless model family is manipulated. | R24: Balanced accuracy | S24: Macro-F1; class-wise recall; accuracy | T24: Jackknife-style omission analysis against the locked baseline. | U24: Use to assess whether the main result is overly dependent on a small subset of sessions. | V24: Directionally stable conclusions across omission reruns. | W24: Large swings or reversals after omitting a single subset. | X24: Repeated-measures dependence, influential sessions, small-sample fragility. | Y24: Chapter 4 Supporting robustness | Z24: Sensitivity evidence only; narrows claims if instability appears. | AA24: Planned | AB24: Khaled (thesis author) | AE24: New reliability-focused robustness experiment.
A25: E24 | B25: Reproducibility rerun audit | C25: Robustness | D25: Primary-supporting robustness | E25: Stage 6 - Robustness analysis | F25: High | G25: Operational reproducibility support | H25: Can the frozen confirmatory package be rerun with matching configs, summaries, and artifact bundles? | I25: A trustworthy final package should be operationally reproducible under the same frozen configuration. | J25: Rerun identity | K25: Dataset index version, train-only fitting policy, metric definitions, seed policy, artifact schema. | L25: Internal repeated-session BAS2 dataset (sub-001 and sub-002) unless explicitly external. | M25: coarse_affect unless this experiment manipulates target granularity. | N25: frozen rerun of the locked confirmatory analysis | O25: Low scientific leakage risk but high trustworthiness risk if reruns diverge. | P25: Frozen config hash, rerun comparison, artifact and summary verification. | Q25: Final locked model and pipeline | R25: Balanced accuracy | S25: Artifact hash agreement; summary agreement | T25: Deterministic rerun comparison under frozen configuration. | U25: Require rerun agreement before treating the package as defense-ready. | V25: Matching configs, stable summaries, and auditable artifact agreement. | W25: Config drift, artifact mismatch, or unexplained rerun divergence. | X25: Operational reproducibility risk, tool drift, environment mismatch. | Y25: Appendix / Method audit | Z25: Operational reproducibility only; strengthens trustworthiness but is not itself the main scientific claim. | AA25: Planned | AB25: Khaled (thesis author) | AE25: New audit-focused experiment.

Sheet Experiment_Definitions
A1: experiment_id | B1: enabled | C1: start_section | D1: end_section | E1: base_artifact_id | F1: target | G1: cv | H1: model | I1: subject | J1: train_subject | K1: test_subject | L1: filter_task | M1: filter_modality | N1: reuse_policy | O1: search_space_id
A2: E01 | B2: Yes | C2: dataset_selection | D2: evaluation | F2: coarse_affect | G2: within_subject_loso_session | H2: ridge | N2: require_explicit_base | O2: SS05
A3: E02 | B3: Yes | C3: dataset_selection | D3: evaluation | F3: coarse_affect | G3: within_subject_loso_session | H3: ridge | L3: VARIES | N3: require_explicit_base
A4: E03 | B4: No | C4: dataset_selection | D4: evaluation | F4: coarse_affect | G4: within_subject_loso_session | H4: ridge | M4: VARIES | N4: require_explicit_base
A5: E04 | B5: No | C5: dataset_selection | D5: evaluation | F5: coarse_affect | G5: VARIES_SPLIT | H5: ridge | N5: require_explicit_base
A6: E05 | B6: No | C6: dataset_selection | D6: evaluation | F6: coarse_affect | G6: frozen_cross_person_transfer | H6: ridge | J6: VARIES | K6: VARIES | N6: require_explicit_base
A7: E06 | B7: No | C7: dataset_selection | D7: evaluation | F7: coarse_affect | G7: within_subject_loso_session | H7: VARIES | N7: require_explicit_base | O7: SS01
A8: E07 | B8: No | C8: dataset_selection | D8: evaluation | F8: coarse_affect | G8: within_subject_loso_session | H8: VARIES | N8: require_explicit_base | O8: SS02
A9: E08 | B9: No | C9: dataset_selection | D9: evaluation | F9: coarse_affect | G9: within_subject_loso_session | H9: VARIES | N9: require_explicit_base | O9: SS03
A10: E12 | B10: No | C10: dataset_selection | D10: evaluation | F10: coarse_affect | G10: within_subject_loso_session | H10: ridge | N10: auto
A11: E13 | B11: No | C11: dataset_selection | D11: evaluation | F11: coarse_affect | G11: within_subject_loso_session | H11: dummy_or_majority | I11: None | N11: auto
A12: E14 | B12: No | C12: dataset_selection | D12: interpretability | F12: coarse_affect | G12: within_subject_loso_session | H12: ridge | N12: reuse_confirmatory_base
A13: E15 | B13: No | C13: dataset_selection | D13: evaluation | F13: coarse_affect | G13: within_subject_loso_session | H13: ridge | L13: VARIES | M13: VARIES | N13: require_explicit_base
A14: E16 | B14: Yes | C14: dataset_selection | D14: evaluation | F14: coarse_affect | G14: within_subject_loso_session | H14: ridge | I14: sub-001 | N14: auto
A15: E17 | B15: No | C15: dataset_selection | D15: evaluation | F15: coarse_affect | G15: frozen_cross_person_transfer | H15: ridge | J15: sub-001 | K15: sub-002 | N15: auto
A16: E20 | B16: No | C16: dataset_selection | D16: evaluation | F16: VARIES_DIAGNOSTIC | G16: within_subject_loso_session | H16: ridge | N16: require_explicit_base
A17: E21 | B17: No | C17: dataset_selection | D17: evaluation | F17: coarse_affect | G17: leave_task_out_within_subject | H17: ridge | L17: HELD_OUT_TASK | N17: require_explicit_base
A18: E22 | B18: No | C18: dataset_selection | D18: evaluation | F18: coarse_affect | G18: leave_modality_out_within_subject | H18: ridge | M18: HELD_OUT_MODALITY | N18: require_explicit_base
A19: E23 | B19: No | C19: dataset_selection | D19: evaluation | F19: coarse_affect | G19: session_influence_jackknife | H19: ridge | N19: require_explicit_base | O19: SS04
A20: E24 | B20: No | C20: dataset_selection | D20: evaluation | F20: coarse_affect | G20: within_subject_loso_session | H20: ridge | N20: reuse_frozen_confirmatory

Sheet Search_Spaces
A1: Search Space Definitions
A2: search_space_id | B2: enabled | C2: optimization_mode | D2: parameter_name | E2: parameter_values | F2: parameter_scope | G2: objective_metric | H2: max_trials | I2: notes
A3: SS01 | B3: No | C3: deterministic_grid | D3: model | E3: ridge|logreg|linearsvc | F3: parameter | G3: balanced_accuracy | I3: Fixed model-family comparison space for E06.
A4: SS02 | B4: No | C4: deterministic_grid | D4: class_weight | E4: none|balanced | F4: parameter | G4: balanced_accuracy | I4: Simple weighting comparison for E07.
A5: SS03 | B5: No | C5: grouped_nested_search | D5: C | E5: 0.01|0.1|1|10 | F5: parameter | G5: balanced_accuracy | H5: 24 | I5: Grouped nested tuning candidate for linear models in E08.
A6: SS03 | B6: No | C6: grouped_nested_search | D6: penalty | E6: l2 | F6: parameter | G6: balanced_accuracy | H6: 24 | I6: Keep tuning space narrow for thesis defensibility.
A7: SS04 | B7: No | C7: deterministic_grid | D7: subset_policy | E7: leave_one_session_out|omit_one_session_train_pool | F7: parameter | G7: balanced_accuracy | I7: Sensitivity space for E23 session-influence checks.
A8: SS05 | B8: Yes | C8: deterministic_grid | D8: target | E8: coarse_affect|emotion|binary_valence_like | F8: parameter | G8: balanced_accuracy | I8: Workbook-executable target grid for E01 target-lock comparison.
A9: SS05 | B9: Yes | C9: deterministic_grid | D9: subject | E9: sub-001|sub-002 | F9: parameter | G9: balanced_accuracy | I9: Subject expansion for workbook-executable E01 target-lock comparison.

Sheet Study_Design
A1: Study Design (Factorial and Custom Matrices)
A2: study_id | B2: study_name | C2: enabled | D2: study_type | E2: intent | F2: question | G2: generalization_claim | H2: start_section | I2: end_section | J2: base_artifact_id | K2: primary_metric | L2: secondary_metrics | M2: cv_scheme | N2: nested_cv | O2: external_validation_planned | P2: blocking_strategy | Q2: randomization_strategy | R2: replication_mode | S2: replication_strategy | T2: num_repeats | U2: random_seed_policy | V2: stopping_rule | W2: notes
A3: S01 | B3: Method-lock core study | C3: No | D3: custom_matrix | E3: exploratory | F3: Which target, split, model, weighting, and tuning choices should be locked before confirmatory analysis? | G3: Supports only method-choice decisions for the current dataset. | H3: dataset_selection | I3: evaluation | J3: method_lock_v1 | K3: balanced_accuracy | L3: macro_f1|accuracy|class_recall | M3: claim_matched_by_experiment | N3: No | O3: No | P3: by_subject | Q3: fixed_order | R3: fixed_repeats | S3: fixed_repeats | T3: 1 | U3: fixed | V3: Complete all listed method-lock cells. | W3: Covers E01-E08.
A4: S02 | B4: Confirmatory within-person study | C4: No | D4: single_experiment | E4: confirmatory | F4: Does the locked pipeline generalize to unseen sessions within each participant? | G4: Within-person held-out-session claim only. | H4: dataset_selection | I4: evaluation | J4: confirm_within_v1 | K4: balanced_accuracy | L4: macro_f1|accuracy|class_recall | M4: within_subject_loso_session | N4: No | O4: No | P4: by_subject | Q4: fixed_order | R4: fixed_repeats | S4: fixed_repeats | T4: 1 | U4: fixed | V4: Stop only after all subjects are run. | W4: Primary Chapter 4 result; linked to E16 plus E12-E14.
A5: S03 | B5: Confirmatory cross-person transfer study | C5: No | D5: single_experiment | E5: confirmatory | F5: Does the frozen mapping transfer across participants under directional train/test separation? | G5: Directional cross-person transfer only; not population inference. | H5: dataset_selection | I5: evaluation | J5: confirm_transfer_v1 | K5: balanced_accuracy | L5: macro_f1|accuracy|class_recall | M5: frozen_cross_person_transfer | N5: No | O5: No | P5: by_subject_pair | Q5: fixed_order | R5: fixed_repeats | S5: fixed_repeats | T5: 2 | U5: fixed | V5: Run both transfer directions. | W5: Primary Chapter 4 transfer result; linked to E17.
A6: S04 | B6: Robustness extension study | C6: No | D6: custom_matrix | E6: exploratory | F6: Do the main conclusions survive confound diagnostics, temporal separation, task/modality holdout, and session-influence checks? | G6: Supports interpretation and limitation boundaries, not the core claim by itself. | H6: dataset_selection | I6: evaluation | J6: robustness_pack_v1 | K6: balanced_accuracy | L6: macro_f1|accuracy|stability_metrics | M6: experiment_specific | N6: No | O6: No | P6: by_subject | Q6: fixed_order | R6: fixed_repeats | S6: fixed_repeats | T6: 1 | U6: fixed | V6: Complete all planned robustness checks or document omissions. | W6: Covers E20-E23.
A7: S05 | B7: Reproducibility and audit study | C7: No | D7: single_experiment | E7: exploratory | F7: Can the frozen confirmatory package be rerun deterministically with matching artifacts and summaries? | G7: Operational reproducibility of the locked pipeline. | H7: dataset_selection | I7: evaluation | J7: repro_audit_v1 | K7: balanced_accuracy | L7: artifact_hash_match|summary_match | M7: within_subject_loso_session | N7: No | O7: No | P7: by_run | Q7: fixed_order | R7: fixed_repeats | S7: fixed_repeats | T7: 2 | U7: fixed | V7: Stop after two clean reruns are compared. | W7: Covers E24 and supports discussion/auditability.

Sheet Study_Rigor_Checklist
A1: Study Rigor Checklist
A2: study_id | B2: leakage_risk_reviewed | C2: deployment_boundary_defined | D2: unit_of_analysis_defined | E2: data_hierarchy_defined | F2: missing_data_plan | G2: class_imbalance_plan | H2: subgroup_plan | I2: fairness_or_applicability_notes | J2: reporting_checklist_completed | K2: risk_of_bias_reviewed | L2: confirmatory_lock_applied | M2: analysis_notes
A3: S01 | B3: Yes | C3: Yes | D3: Yes | E3: Yes | F3: Yes | G3: Yes | H3: Yes | I3: Method-lock work should not be presented as final performance evidence. | J3: No | K3: Yes | L3: No | M3: Use only for design locking.
